Workbook
Name konštrukcie: [1]zoznamy!$A$3:$A$10
Name materialy: [1]zoznamy!$F$3:$F$65541
Name odpory: [1]zoznamy!$C$3:$C$6
Name systém: [1]zoznamy!$AB$2:$AB$3

Sheet Legenda
A1: LEGENDA:
B2: Položka výpočtu
B3: Popis
B4: Doplň hodnotu
B5: Vyráta sa automaticky
A7: VSTUPNÉ ÚDAJE: | C7: MJ.
B8: Typ budovy | C8: -
B9: Lokalita | C9: -
B10: Merná plocha | C10: m²
B11: Vykurovaný objem | C11: m³

Sheet Výpočet_normalizovaný
A1: 1. Budova | B1: =Legenda!A8 -> 0 | C1: Výpočet pre normalizované podmienky
A2: Obostavaný objem (m³) | C2: Merná plocha (m²)
A3: Vb= | B3: =Legenda!A11 -> 0 | C3: Ab= | D3: =Legenda!A10 -> 0
A4: Budova | B4: nová | C4: Priemerná konštrukčná výška vykurovaných podlaží (m)
B5: pôvodná/obnovená | C5: hk,pr= | D5: =B3/D3 -> #DIV/0!
A6: 2. Merná tepelná strata prechodom tepla HT (W/K) | E6: Cieľová hodnota od 1.1.2021 normalizovaná (požadovaná) / odporúčaná | I6: % podiel mernej tepelnej straty prechodom k celkovým tepelným stratám prechodom
A7: Konštrukcia | C7: Plocha Ai (m²) | D7: Ui (W/(m².K)) | E7: Uw,r2 (W/(m².K)) / Uw,r3 (W/(m².K)) | F7: Ui . Ai (W/K) | G7: Faktor bx (-) | H7: bx.Ui.Ai (W/K) | I7: %
A8: vonkajšia stena | E8: ≤ 0,22 / 0,15 | F8: =C8*D8 -> 0 | G8: 1 | H8: =G8*F8 -> 0 | I8: =H8/H16 -> #DIV/0!
A9: vonkajšie okná v obvodovej stene (vrátane balkónových, terasových dverí a franúzkych okie) | E9: ≤ 0,85 / 0,65 | F9: =C9*D9 -> 0 | G9: 1 | H9: =G9*F9 -> 0 | I9: =H9/H16 -> #DIV/0!
A10: vonkajšie dvere bez zádveria | E10: ≤ 2,00 / 2,00 | F10: =C10*D10 -> 0 | G10: 1 | H10: =G10*F10 -> 0 | I10: =H10/H16 -> #DIV/0!
A11: strecha na teplovýmennom obale budovy, plochá a šikmá strecha so sklonom ≤ 45° | E11: ≤ 0,15 / 0,10 | F11: =C11*D11 -> 0 | G11: 1 | H11: =G11*F11 -> 0 | I11: =H11/H16 -> #DIV/0!
A12: stena medzi vykurovaným a nevykurovaným priestorom a podstrešným priestorom | E12: Podľa rozdielu teplôt a tepelného toku vodorovne, zhora nadol, zdola nahor, viď STN 73 3540-2+Z1+Z2: 2019 | F12: =C12*D12 -> 0 | G12: 0.8 | H12: =G12*F12 -> 0 | I12: =H12/H16 -> #DIV/0!
A13: stena a strop do nevykurovaného priestoru (suterénu) | F13: =C13*D13 -> 0 | G13: 0.5 | H13: =G13*F13 -> 0 | I13: =H13/H16 -> #DIV/0!
A14: stena a strop do temperovaného priestoru (garáž, susedná budova) | F14: =C14*D14 -> 0 | G14: 0.35 | H14: =G14*F14 -> 0 | I14: =H14/H16 -> #DIV/0!
A15: strop nad otvoreným prejazdom | E15: ≤ 0,20 / 0,15 | F15: =C15*D15 -> 0 | G15: 1 | H15: =G15*F15 -> 0 | I15: =H15/H16 -> #DIV/0!
A16: Súčty | C16: ∑Ai = | D16: =SUM(C8:C15) -> 0 | G16: ∑bx . Ui . Ai = | H16: =SUM(H8:H15) -> 0 | I16: =#REF!+#REF!+I10+I17+I12+I13+I14+I15+I11 -> #REF!
A17: 3. Započítanie vplyvu tepelných mostov: | C17: exaktne
C18: paušálne
A19: Exaktne: | C19: ΔU = | E19: zadá sa hodnota vypočítaná vzťahom | I19: 0.1
A20: Paušálne: | C20: ΔU = | D20: 0.02 | E20: za predpokladu spojitej tepelnoizolačnej vrtsvy na vonkajšom povrchu konštrukcie a použitia nových systémov murovaných konštrukcií spĺňajúcich aspoň požiadavky normalizované od 1.1.2016
C21: ΔU = | D21: 0.05 | E21: za predpokladu spojitej tepelnoizolačnej vrtsvy na vonkajšom povrchu konštrukcie a použitia nových systémov murovaných konštrukcií najmä po roku 2002
C22: ΔU = | D22: 0.1 | E22: pri murovaných, panelových vrstvených betónových a keramických, ľahkých drevených roštových konštrukciach, kovoplastických obvodových plášťoch (pred ich obnovou)
C23: ΔU = | D23: 0.2 | E23: pri zateplení na vnútornej strane vonkajšej konštrukcie
A24: Vplyv tepelných mostov ΔHTM (W/K) | E24: ΔHTM = ΔU . ∑Ai = | H24: =I19*D16 -> 0
A25: Merná tepelná strata HT (W/K) | E25: HT = ∑bx .Ui . Ai + ΔU . ∑Ai= | H25: =H16+H24 -> 0
A26: Priemerný súčiniteľ prechodu tepla (W/(m².K)) | E26: Um = HT/∑Ai= | H26: =H25/D16 -> #DIV/0!
A27: 4. Merná tepelná strata vetraním HV (W/K) | C27: HV = ρa . Ca . n . V / 3600 | E27: účinnosť rekuperácie | F27: Hv = | G27: =(100-E29)%*1.2*1010*0.85*B29*B3/3600 -> 0
A28: Intenzita výmeny vzduchu (1/h)
A29: n = | B29: 0.5 | E29: 0
A30: 5. Merná tepelná strata H = HT + HV (W/K) | C30: H = | G30: =H25+G27 -> 0
A31: 6. Solárne zisky Qs (kWh) | C31: Fw (-) | D31: gKolmé (-) | E31: Fs.Fc.Ff (-) | F31: Anj (m2)
B32: Juh - J | C32: 0.9 | D32: 0.76 | E32: 0.512
B33: Sever - S | C33: 0.9 | D33: 0.76 | E33: 0.512
B34: Východ - V | C34: 0.9 | D34: 0.76 | E34: 0.512
B35: Západ - Z | C35: 0.9 | D35: 0.76 | E35: 0.512
B36: Juhovýchod - JV | C36: 0.8 | D36: 0.76 | E36: 0.64
B37: Juhozápad - JZ | C37: 0.8 | D37: 0.76 | E37: 0.64
B38: Severovýchod - SV | C38: 0.8 | D38: 0.76 | E38: 0.64
B39: Severozápad - SZ | C39: 0.8 | D39: 0.76 | E39: 0.64
B40: Horizontálna rovina - H | C40: 0.8 | D40: 0.76 | E40: 0.64
...

Sheet Výpočet_lokalita
A1: 1. Budova | B1: =Legenda!A8 -> 0 | C1: Výpočet pre lokálne podmienky | F1: Lokalita: | H1: =Legenda!A9 -> 0
A2: Obostavaný objem (m³) | C2: Merná plocha (m²)
A3: Vb= | B3: =Legenda!A11 -> 0 | C3: Ab= | D3: =Legenda!A10 -> 0
A4: Budova | B4: nová | C4: Priemerná konštrukčná výška vykurovaných podlaží (m)
B5: pôvodná/obnovená | C5: hk,pr= | D5: =B3/D3 -> #DIV/0!
A6: 2. Merná tepelná strata prechodom tepla HT (W/K) | E6: Cieľová hodnota od 1.1.2021 normalizovaná (požadovaná) / odporúčaná | I6: % podiel mernej tepelnej straty prechodom k celkovým tepelným stratám prechodom
A7: Konštrukcia | C7: Plocha Ai (m²) | D7: Ui (W/(m².K)) | E7: Uw,r2 (W/(m².K)) / Uw,r3 (W/(m².K)) | F7: Ui . Ai (W/K) | G7: Faktor bx (-) | H7: bx.Ui.Ai (W/K) | I7: %
A8: vonkajšia stena | E8: ≤ 0,22 / 0,15 | F8: =C8*D8 -> 0 | G8: 1 | H8: =G8*F8 -> 0 | I8: =H8/H17 -> #DIV/0!
A9: vonkajšie okná v obvodovej stene (vrátane balkónových, terasových dverí a franúzkych okie) | E9: ≤ 0,85 / 0,65 | F9: =C9*D9 -> 0 | G9: 1 | H9: =G9*F9 -> 0 | I9: =H9/H17 -> #DIV/0!
A10: vonkajšie dvere bez zádveria | E10: ≤ 2,00 / 2,00 | F10: =C10*D10 -> 0 | G10: 1 | H10: =G10*F10 -> 0 | I10: =H10/H17 -> #DIV/0!
A12: strecha na teplovýmennom obale budovy, plochá a šikmá strecha so sklonom ≤ 45° | E12: ≤ 0,15 / 0,10 | F12: =C12*D12 -> 0 | G12: 1 | H12: =G12*F12 -> 0 | I12: =H12/H17 -> #DIV/0!
A13: stena medzi vykurovaným a nevykurovaným priestorom a podstrešným priestorom | E13: Podľa rozdielu teplôt a tepelného toku vodorovne, zhora nadol, zdola nahor, viď STN 73 3540-2+Z1+Z2: 2019 | F13: =C13*D13 -> 0 | G13: 0.8 | H13: =G13*F13 -> 0 | I13: =H13/H17 -> #DIV/0!
A14: stena a strop do nevykurovaného priestoru (suterénu) | F14: =C14*D14 -> 0 | G14: 0.5 | H14: =G14*F14 -> 0 | I14: =H14/H17 -> #DIV/0!
A15: stena a strop do temperovaného priestoru (garáž, susedná budova) | F15: =C15*D15 -> 0 | G15: 0.35 | H15: =G15*F15 -> 0 | I15: =H15/H17 -> #DIV/0!
A16: strop nad otvoreným prejazdom | E16: ≤ 0,20 / 0,15 | F16: =C16*D16 -> 0 | G16: 1 | H16: =G16*F16 -> 0 | I16: =H16/H17 -> #DIV/0!
A17: Súčty | C17: ∑Ai = | D17: =SUM(C8:C16) -> 0 | G17: ∑bx . Ui . Ai = | H17: =SUM(H8:H16) -> 0 | I17: =I8+I9+I10+I18+I13+I14+I15+I16+I12 -> #DIV/0!
A18: 3. Započítanie vplyvu tepelných mostov: | C18: exaktne
C19: paušálne
A20: Exaktne: | C20: ΔU = | E20: zadá sa hodnota vypočítaná vzťahom | I20: 0.1
A21: Paušálne: | C21: ΔU = | D21: 0.02 | E21: za predpokladu spojitej tepelnoizolačnej vrtsvy na vonkajšom povrchu konštrukcie a použitia nových systémov murovaných konštrukcií spĺňajúcich aspoň požiadavky normalizované od 1.1.2016
C22: ΔU = | D22: 0.05 | E22: za predpokladu spojitej tepelnoizolačnej vrtsvy na vonkajšom povrchu konštrukcie a použitia nových systémov murovaných konštrukcií najmä po roku 2002
C23: ΔU = | D23: 0.1 | E23: pri murovaných, panelových vrstvených betónových a keramických, ľahkých drevených roštových konštrukciach, kovoplastických obvodových plášťoch (pred ich obnovou)
C24: ΔU = | D24: 0.2 | E24: pri zateplení na vnútornej strane vonkajšej konštrukcie
A25: Vplyv tepelných mostov ΔHTM (W/K) | E25: ΔHTM = ΔU . ∑Ai = | H25: =I20*D17 -> 0
A26: Merná tepelná strata HT (W/K) | E26: HT = ∑bx .Ui . Ai + ΔU . ∑Ai= | H26: =H17+H25 -> 0
A27: Priemerný súčiniteľ prechodu tepla (W/(m².K)) | E27: Um = HT/∑Ai= | H27: =H26/D17 -> #DIV/0!
A28: 4. Merná tepelná strata vetraním HV (W/K) | C28: HV = ρa . Ca . n . V / 3600 | E28: účinnosť rekuperácie | F28: Hv = | G28: =(100-E30)%*1.2*1010*0.85*B30*B3/3600 -> 0
A29: Intenzita výmeny vzduchu (1/h)
A30: n = | B30: 0.5 | E30: 0
A31: 5. Merná tepelná strata H = HT + HV (W/K) | C31: H = | G31: =H26+G28 -> 0
A32: 6. Solárne zisky Qs (kWh) | C32: Fw (-) | D32: gKolmé (-) | E32: Fs.Fc.Ff (-) | F32: Anj (m2)
B33: Juh - J | C33: 0.9 | D33: 0.76 | E33: 0.512
B34: Sever - S | C34: 0.9 | D34: 0.76 | E34: 0.512
B35: Východ - V | C35: 0.9 | D35: 0.76 | E35: 0.512
B36: Západ - Z | C36: 0.9 | D36: 0.76 | E36: 0.512
B37: Juhovýchod - JV | C37: 0.8 | D37: 0.76 | E37: 0.64
B38: Juhozápad - JZ | C38: 0.8 | D38: 0.76 | E38: 0.64
B39: Severovýchod - SV | C39: 0.8 | D39: 0.76 | E39: 0.64
B40: Severozápad - SZ | C40: 0.8 | D40: 0.76 | E40: 0.64
B41: Horizontálna rovina - H | C41: 0.8 | D41: 0.76 | E41: 0.64
...

Sheet Mesačný priemer vonk. teploty
A1: Mesačný priemer vonkajšej teploty
A2: STN EN ISO 13790/NA: Tabuľka NA.1 – Regresné vzťahy pre mesačný priemer vonkajšej teploty
A3: pre teplotné oblasti I, II, III podľa rajonizácie na obr. NA.1 až NA.12
A6: Mesto | B6: Nitra | C6: Mesiac | D6: θe (°C) | F6: Mesto | G6: Senica | H6: Mesiac | I6: θe (°C) | K6: Mesto | L6: Topolcany | M6: Mesiac | N6: θe (°C) | P6: Mesto | Q6: Piestany | R6: Mesiac | S6: θe (°C) | U6: Mesto | V6: Zilina | W6: Mesiac | X6: θe (°C)
A7: Oblasť | B7: 1 | C7: I | D7: =-0.004*B$8-1.1 -> -1.64 | F7: Oblasť | G7: 2 | H7: I | I7: =-0.004*G$8-1.8 -> -2.58 | K7: Oblasť | L7: 2 | M7: I | N7: =-0.004*L$8-1.8 -> -2.568 | P7: Oblasť | Q7: 1 | R7: I | S7: =-0.004*Q$8-1.1 -> -1.752 | U7: Oblasť | V7: 2 | W7: I | X7: =-0.004*V$8-1.8 -> -3.26
A8: Nad. v. (m.n.m.) | B8: 135 | C8: II | D8: =-0.005*B$8+1.3 -> 0.625 | F8: Nad. v. (m.n.m.) | G8: 195 | H8: II | I8: =-0.005*G$8+0.6 -> -0.375 | K8: Nad. v. (m.n.m.) | L8: 192 | M8: II | N8: =-0.005*L$8+0.6 -> -0.36 | P8: Nad. v. (m.n.m.) | Q8: 163 | R8: II | S8: =-0.005*Q$8+1.3 -> 0.485 | U8: Nad. v. (m.n.m.) | V8: 365 | W8: II | X8: =-0.005*V$8+0.6 -> -1.225
C9: III | D9: =-0.006*B$8+6.2 -> 5.39 | H9: III | I9: =-0.006*G$8+5.3 -> 4.13 | M9: III | N9: =-0.006*L$8+5.3 -> 4.148 | R9: III | S9: =-0.006*Q$8+6.2 -> 5.222 | W9: III | X9: =-0.006*V$8+5.3 -> 3.11
C10: IV | D10: =-0.007*B$8+11.7 -> 10.755 | H10: IV | I10: =-0.007*G$8+11.1 -> 9.735 | M10: IV | N10: =-0.007*L$8+11.1 -> 9.756 | R10: IV | S10: =-0.007*Q$8+11.7 -> 10.559 | W10: IV | X10: =-0.007*V$8+11.1 -> 8.545
C11: V | D11: =-0.007*B$8+16.6 -> 15.655 | H11: V | I11: =-0.007*G$8+16 -> 14.635 | M11: V | N11: =-0.007*L$8+16 -> 14.656 | R11: V | S11: =-0.007*Q$8+16.6 -> 15.459 | W11: V | X11: =-0.007*V$8+16 -> 13.445
C12: VI | D12: =-0.0075*B$8+19.7 -> 18.6875 | H12: VI | I12: =-0.0075*G$8+19.1 -> 17.6375 | M12: VI | N12: =-0.0075*L$8+19.1 -> 17.66 | R12: VI | S12: =-0.0075*Q$8+19.7 -> 18.4775 | W12: VI | X12: =-0.0075*V$8+19.1 -> 16.3625
C13: VII | D13: =-0.0075*B$8+21.4 -> 20.3875 | H13: VII | I13: =-0.0075*G$8+20.7 -> 19.2375 | M13: VII | N13: =-0.0075*L$8+20.7 -> 19.26 | R13: VII | S13: =-0.0075*Q$8+21.4 -> 20.1775 | W13: VII | X13: =-0.0075*V$8+20.7 -> 17.9625
C14: VIII | D14: =-0.0075*B$8+20.8 -> 19.7875 | H14: VIII | I14: =-0.0075*G$8+20.1 -> 18.6375 | M14: VIII | N14: =-0.0075*L$8+20.1 -> 18.66 | R14: VIII | S14: =-0.0075*Q$8+20.8 -> 19.5775 | W14: VIII | X14: =-0.0075*V$8+20.1 -> 17.3625
C15: IX | D15: =-0.0065*B$8+16.3 -> 15.4225 | H15: IX | I15: =-0.0065*G$8+15.7 -> 14.4325 | M15: IX | N15: =-0.0065*L$8+15.7 -> 14.452 | R15: IX | S15: =-0.0065*Q$8+16.3 -> 15.2405 | W15: IX | X15: =-0.0065*V$8+15.7 -> 13.3275
C16: X | D16: =-0.005*B$8+10.7 -> 10.025 | H16: X | I16: =-0.005*G$8+10.2 -> 9.225 | M16: X | N16: =-0.005*L$8+10.2 -> 9.24 | R16: X | S16: =-0.005*Q$8+10.7 -> 9.885 | W16: X | X16: =-0.005*V$8+10.2 -> 8.375
C17: XI | D17: =-0.0045*B$8+5.1 -> 4.4925 | H17: XI | I17: =-0.0045*G$8+4.7 -> 3.8225 | M17: XI | N17: =-0.0045*L$8+4.7 -> 3.836 | R17: XI | S17: =-0.0045*Q$8+5.1 -> 4.3665 | W17: XI | X17: =-0.0045*V$8+4.7 -> 3.0575
C18: XII | D18: =-0.0045*B$8+0.5 -> -0.1075 | H18: XII | I18: =-0.0045*G$8+0.1 -> -0.7775 | M18: XII | N18: =-0.0045*L$8+0.1 -> -0.764 | R18: XII | S18: =-0.0045*Q$8+0.5 -> -0.2335 | W18: XII | X18: =-0.0045*V$8+0.1 -> -1.5425
A20: Mesto | B20: Dolny Kubin | C20: Mesiac | D20: θe (°C) | F20: Mesto | G20: Banska Bystrica | H20: Mesiac | I20: θe (°C) | K20: Mesto | L20: Trebisov | M20: Mesiac | N20: θe (°C) | P20: Mesto | Q20: Bardejov | R20: Mesiac | S20: θe (°C) | U20: Mesto | V20: Presov | W20: Mesiac | X20: θe (°C)
A21: Oblasť | B21: 2 | C21: I | D21: =-0.004*B$22-1.8 -> -3.672 | F21: Oblasť | G21: 2 | H21: I | I21: =-0.004*G$22-1.8 -> -3.516 | K21: Oblasť | L21: 2 | M21: I | N21: =-0.004*L$22-1.8 -> -2.22 | P21: Oblasť | Q21: 2 | R21: I | S21: =-0.004*Q$22-1.8 -> -3.02 | U21: Oblasť | V21: 2 | W21: I | X21: =-0.004*V$22-1.8 -> -3.028
A22: Nad. v. (m.n.m.) | B22: 468 | C22: II | D22: =-0.005*B$22+0.6 -> -1.74 | F22: Nad. v. (m.n.m.) | G22: 429 | H22: II | I22: =-0.005*G$22+0.6 -> -1.545 | K22: Nad. v. (m.n.m.) | L22: 105 | M22: II | N22: =-0.005*L$22+0.6 -> 0.075 | P22: Nad. v. (m.n.m.) | Q22: 305 | R22: II | S22: =-0.005*Q$22+0.6 -> -0.925 | U22: Nad. v. (m.n.m.) | V22: 307 | W22: II | X22: =-0.005*V$22+0.6 -> -0.935
C23: III | D23: =-0.006*B$22+5.3 -> 2.492 | H23: III | I23: =-0.006*G$22+5.3 -> 2.726 | M23: III | N23: =-0.006*L$22+5.3 -> 4.67 | R23: III | S23: =-0.006*Q$22+5.3 -> 3.47 | W23: III | X23: =-0.006*V$22+5.3 -> 3.458
C24: IV | D24: =-0.007*B$22+11.1 -> 7.824 | H24: IV | I24: =-0.007*G$22+11.1 -> 8.097 | M24: IV | N24: =-0.007*L$22+11.1 -> 10.365 | R24: IV | S24: =-0.007*Q$22+11.1 -> 8.965 | W24: IV | X24: =-0.007*V$22+11.1 -> 8.951
C25: V | D25: =-0.007*B$22+16 -> 12.724 | H25: V | I25: =-0.007*G$22+16 -> 12.997 | M25: V | N25: =-0.007*L$22+16 -> 15.265 | R25: V | S25: =-0.007*Q$22+16 -> 13.865 | W25: V | X25: =-0.007*V$22+16 -> 13.851
C26: VI | D26: =-0.0075*B$22+19.1 -> 15.59 | H26: VI | I26: =-0.0075*G$22+19.1 -> 15.8825 | M26: VI | N26: =-0.0075*L$22+19.1 -> 18.3125 | R26: VI | S26: =-0.0075*Q$22+19.1 -> 16.8125 | W26: VI | X26: =-0.0075*V$22+19.1 -> 16.7975
C27: VII | D27: =-0.0075*B$22+20.7 -> 17.19 | H27: VII | I27: =-0.0075*G$22+20.7 -> 17.4825 | M27: VII | N27: =-0.0075*L$22+20.7 -> 19.9125 | R27: VII | S27: =-0.0075*Q$22+20.7 -> 18.4125 | W27: VII | X27: =-0.0075*V$22+20.7 -> 18.3975
C28: VIII | D28: =-0.0075*B$22+20.1 -> 16.59 | H28: VIII | I28: =-0.0075*G$22+20.1 -> 16.8825 | M28: VIII | N28: =-0.0075*L$22+20.1 -> 19.3125 | R28: VIII | S28: =-0.0075*Q$22+20.1 -> 17.8125 | W28: VIII | X28: =-0.0075*V$22+20.1 -> 17.7975
C29: IX | D29: =-0.0065*B$22+15.7 -> 12.658 | H29: IX | I29: =-0.0065*G$22+15.7 -> 12.9115 | M29: IX | N29: =-0.0065*L$22+15.7 -> 15.0175 | R29: IX | S29: =-0.0065*Q$22+15.7 -> 13.7175 | W29: IX | X29: =-0.0065*V$22+15.7 -> 13.7045
C30: X | D30: =-0.005*B$22+10.2 -> 7.86 | H30: X | I30: =-0.005*G$22+10.2 -> 8.055 | M30: X | N30: =-0.005*L$22+10.2 -> 9.675 | R30: X | S30: =-0.005*Q$22+10.2 -> 8.675 | W30: X | X30: =-0.005*V$22+10.2 -> 8.665
C31: XI | D31: =-0.0045*B$22+4.7 -> 2.594 | H31: XI | I31: =-0.0045*G$22+4.7 -> 2.7695 | M31: XI | N31: =-0.0045*L$22+4.7 -> 4.2275 | R31: XI | S31: =-0.0045*Q$22+4.7 -> 3.3275 | W31: XI | X31: =-0.0045*V$22+4.7 -> 3.3185
C32: XII | D32: =-0.0045*B$22+0.1 -> -2.006 | H32: XII | I32: =-0.0045*G$22+0.1 -> -1.8305 | M32: XII | N32: =-0.0045*L$22+0.1 -> -0.3725 | R32: XII | S32: =-0.0045*Q$22+0.1 -> -1.2725 | W32: XII | X32: =-0.0045*V$22+0.1 -> -1.2815
A34: Mesto | B34: Bratislava-letisko | C34: Mesiac | D34: θe (°C) | F34: Mesto | G34: Košice-letisko | H34: Mesiac | I34: θe (°C) | K34: Mesto | L34: Poprad | M34: Mesiac | N34: θe (°C) | P34: Mesto | Q34: Liptovský Mikuláš | R34: Mesiac | S34: θe (°C) | U34: Mesto | V34: Oravská Lesná | W34: Mesiac | X34: θe (°C)
A35: Oblasť | B35: 1 | C35: I | D35: =-0.004*B$36-1.1 -> -1.632 | F35: Oblasť | G35: 2 | H35: I | I35: =-0.004*G$36-1.8 -> -2.72 | K35: Oblasť | L35: 3 | M35: I | N35: =-0.004*L$36-2.5 -> -5.276 | P35: Oblasť | Q35: 2 | R35: I | S35: =-0.004*Q$36-1.8 -> -4.076 | U35: Oblasť | V35: 3 | W35: I | X35: =-0.004*V$36-2.5 -> -5.62
A36: Nad. v. (m.n.m.) | B36: 133 | C36: II | D36: =-0.005*B$36+1.3 -> 0.635 | F36: Nad. v. (m.n.m.) | G36: 230 | H36: II | I36: =-0.005*G$36+0.6 -> -0.55 | K36: Nad. v. (m.n.m.) | L36: 694 | M36: II | N36: =-0.005*L$36-0.1 -> -3.57 | P36: Nad. v. (m.n.m.) | Q36: 569 | R36: II | S36: =-0.005*Q$36+0.6 -> -2.245 | U36: Nad. v. (m.n.m.) | V36: 780 | W36: II | X36: =-0.005*V$36-0.1 -> -4
C37: III | D37: =-0.006*B$36+6.2 -> 5.402 | H37: III | I37: =-0.006*G$36+5.3 -> 3.92 | M37: III | N37: =-0.006*L$36+4.4 -> 0.236 | R37: III | S37: =-0.006*Q$36+5.3 -> 1.886 | W37: III | X37: =-0.006*V$36+4.4 -> -0.28
C38: IV | D38: =-0.007*B$36+11.7 -> 10.769 | H38: IV | I38: =-0.007*G$36+11.1 -> 9.49 | M38: IV | N38: =-0.007*L$36+10.4 -> 5.542 | R38: IV | S38: =-0.007*Q$36+11.1 -> 7.117 | W38: IV | X38: =-0.007*V$36+10.4 -> 4.94
C39: V | D39: =-0.007*B$36+16.6 -> 15.669 | H39: V | I39: =-0.007*G$36+16 -> 14.39 | M39: V | N39: =-0.007*L$36+15.4 -> 10.542 | R39: V | S39: =-0.007*Q$36+16 -> 12.017 | W39: V | X39: =-0.007*V$36+15.4 -> 9.94
C40: VI | D40: =-0.0075*B$36+19.7 -> 18.7025 | H40: VI | I40: =-0.0075*G$36+19.1 -> 17.375 | M40: VI | N40: =-0.0075*L$36+18.5 -> 13.295 | R40: VI | S40: =-0.0075*Q$36+19.1 -> 14.8325 | W40: VI | X40: =-0.0075*V$36+18.5 -> 12.65
C41: VII | D41: =-0.0075*B$36+21.4 -> 20.4025 | H41: VII | I41: =-0.0075*G$36+20.7 -> 18.975 | M41: VII | N41: =-0.0075*L$36+20 -> 14.795 | R41: VII | S41: =-0.0075*Q$36+20.7 -> 16.4325 | W41: VII | X41: =-0.0075*V$36+20 -> 14.15
C42: VIII | D42: =-0.0075*B$36+20.8 -> 19.8025 | H42: VIII | I42: =-0.0075*G$36+20.1 -> 18.375 | M42: VIII | N42: =-0.0075*L$36+19.4 -> 14.195 | R42: VIII | S42: =-0.0075*Q$36+20.1 -> 15.8325 | W42: VIII | X42: =-0.0075*V$36+19.4 -> 13.55
C43: IX | D43: =-0.0065*B$36+16.3 -> 15.4355 | H43: IX | I43: =-0.0065*G$36+15.7 -> 14.205 | M43: IX | N43: =-0.0065*L$36+16 -> 11.489 | R43: IX | S43: =-0.0065*Q$36+15.7 -> 12.0015 | W43: IX | X43: =-0.0065*V$36+16 -> 10.93
C44: X | D44: =-0.005*B$36+10.7 -> 10.035 | H44: X | I44: =-0.005*G$36+10.2 -> 9.05 | M44: X | N44: =-0.005*L$36+9.6 -> 6.13 | R44: X | S44: =-0.005*Q$36+10.2 -> 7.355 | W44: X | X44: =-0.005*V$36+9.6 -> 5.7
...

Sheet Intenzita sln. žiarenia
A1: Intenzita slnečného žiarenia
A2: STN EN ISO 13790/NA: Tabuľka NA.8 – Priemerné mesačné sumy globálneho žiarenia na horizontálnu plochu (0°)
A3: vypočítané pre vybrané klimatologické stanice na Slovensku za obdobie 1951 – 1980 v kWh/m².
A5: Pri rozdiele nadmorskej výšky lokality umiestnenia budovy a nadmorskej výšky vybranej najbližšej stanice o viac ako 100 m sa uplatní vertikálny gradient poklesu globálneho žiarenia na vodorovnú plochu v teplom polroku (mesiace IV – IX) v % podľa tabuľky NA.9. | AM5: PRIDANÉ
A7: Horizontálna rovina | I7: Sklon 30° | W7: Sklon 60° | AM7: Sklon 90° | BC7: Sklon 45° (interpolácia)
A9: month | B9: days | C9: hours | D9: horizontal | J9: South | M9: North | P9: East | S9: West | Z9: South | AC9: North | AF9: East | AI9: West | AP9: South | AS9: North | AV9: East | AY9: West | BD9: South | BF9: North | BH9: East | BJ9: West
D10: W/m2 | E10: kWh/m2 | J10: kvoc | K10: W/m2 | L10: kWh/m2 | M10: kvoc | N10: W/m2 | O10: kWh/m2 | P10: kvoc | Q10: W/m2 | R10: kWh/m2 | S10: kvoc | T10: W/m2 | U10: kWh/m2 | Z10: kvoc | AA10: W/m2 | AB10: kWh/m2 | AC10: kvoc | AD10: W/m2 | AE10: kWh/m2 | AF10: kvoc | AG10: W/m2 | AH10: kWh/m2 | AI10: kvoc | AJ10: W/m2 | AK10: kWh/m2 | AP10: kvoc | AQ10: W/m2 | AR10: kWh/m2 | AS10: kvoc | AT10: W/m2 | AU10: kWh/m2 | AV10: kvoc | AW10: W/m2 | AX10: kWh/m2 | AY10: kvoc | AZ10: W/m2 | BA10: kWh/m2 | BD10: W/m2 | BE10: kWh/m2 | BF10: W/m2 | BG10: kWh/m2 | BH10: W/m2 | BI10: kWh/m2 | BJ10: W/m2 | BK10: kWh/m2
A11: I | B11: 31 | C11: =B11*24 -> 744 | D11: =E11*1000/C11 -> 34.946237 | E11: 26 | J11: 1.62 | K11: =J11*$D11 -> 56.612903 | L11: =$E11*J11 -> 42.12 | M11: 0.5 | N11: =M11*$D11 -> 17.473118 | O11: =$E11*M11 -> 13 | P11: 1 | Q11: =P11*$D11 -> 34.946237 | R11: =$E11*P11 -> 26 | S11: 1 | T11: =S11*$D11 -> 34.946237 | U11: =$E11*S11 -> 26 | Z11: 1.96 | AA11: =Z11*$D11 -> 68.494624 | AB11: =$E11*Z11 -> 50.96 | AC11: 0.49 | AD11: =AC11*$D11 -> 17.123656 | AE11: =$E11*AC11 -> 12.74 | AF11: 0.95 | AG11: =AF11*$D11 -> 33.198925 | AH11: =$E11*AF11 -> 24.7 | AI11: 0.95 | AJ11: =AI11*$D11 -> 33.198925 | AK11: =$E11*AI11 -> 24.7 | AP11: 1.94 | AQ11: =AP11*$D11 -> 67.795699 | AR11: =$E11*AP11 -> 50.44 | AS11: 0.53 | AT11: =AS11*$D11 -> 18.521505 | AU11: =$E11*AS11 -> 13.78 | AV11: 0.85 | AW11: =AV11*$D11 -> 29.704301 | AX11: =$E11*AV11 -> 22.1 | AY11: 0.85 | AZ11: =AY11*$D11 -> 29.704301 | BA11: =$E11*AY11 -> 22.1 | BD11: =(K11+AQ11)/2 -> 62.204301 | BE11: =(L11+AR11)/2 -> 46.28 | BF11: =(N11+AT11)/2 -> 17.997312 | BG11: =(O11+AU11)/2 -> 13.39 | BH11: =(Q11+AW11)/2 -> 32.325269 | BI11: =(R11+AX11)/2 -> 24.05 | BJ11: =(T11+AZ11)/2 -> 32.325269 | BK11: =(U11+BA11)/2 -> 24.05
A12: II | B12: 28 | C12: =B12*24 -> 672 | D12: =E12*1000/C12 -> 72.916667 | E12: 49 | J12: 1.46 | K12: =J12*$D12 -> 106.45833 | L12: =$E12*J12 -> 71.54 | M12: 0.43 | N12: =M12*$D12 -> 31.354167 | O12: =$E12*M12 -> 21.07 | P12: 0.99 | Q12: =P12*$D12 -> 72.1875 | R12: =$E12*P12 -> 48.51 | S12: 0.99 | T12: =S12*$D12 -> 72.1875 | U12: =$E12*S12 -> 48.51 | Z12: 1.65 | AA12: =Z12*$D12 -> 120.3125 | AB12: =$E12*Z12 -> 80.85 | AC12: 0.41 | AD12: =AC12*$D12 -> 29.895833 | AE12: =$E12*AC12 -> 20.09 | AF12: 0.91 | AG12: =AF12*$D12 -> 66.354167 | AH12: =$E12*AF12 -> 44.59 | AI12: 0.91 | AJ12: =AI12*$D12 -> 66.354167 | AK12: =$E12*AI12 -> 44.59 | AP12: 1.53 | AQ12: =AP12*$D12 -> 111.5625 | AR12: =$E12*AP12 -> 74.97 | AS12: 0.44 | AT12: =AS12*$D12 -> 32.083333 | AU12: =$E12*AS12 -> 21.56 | AV12: 0.78 | AW12: =AV12*$D12 -> 56.875 | AX12: =$E12*AV12 -> 38.22 | AY12: 0.78 | AZ12: =AY12*$D12 -> 56.875 | BA12: =$E12*AY12 -> 38.22 | BD12: =(K12+AQ12)/2 -> 109.01042 | BE12: =(L12+AR12)/2 -> 73.255 | BF12: =(N12+AT12)/2 -> 31.71875 | BG12: =(O12+AU12)/2 -> 21.315 | BH12: =(Q12+AW12)/2 -> 64.53125 | BI12: =(R12+AX12)/2 -> 43.365 | BJ12: =(T12+AZ12)/2 -> 64.53125 | BK12: =(U12+BA12)/2 -> 43.365
A13: III | B13: 31 | C13: =B13*24 -> 744 | D13: =E13*1000/C13 -> 118.27957 | E13: 88 | J13: 1.26 | K13: =J13*$D13 -> 149.03226 | L13: =$E13*J13 -> 110.88 | M13: 0.51 | N13: =M13*$D13 -> 60.322581 | O13: =$E13*M13 -> 44.88 | P13: 0.96 | Q13: =P13*$D13 -> 113.54839 | R13: =$E13*P13 -> 84.48 | S13: 0.96 | T13: =S13*$D13 -> 113.54839 | U13: =$E13*S13 -> 84.48 | Z13: 1.28 | AA13: =Z13*$D13 -> 151.39785 | AB13: =$E13*Z13 -> 112.64 | AC13: 0.33 | AD13: =AC13*$D13 -> 39.032258 | AE13: =$E13*AC13 -> 29.04 | AF13: 0.84 | AG13: =AF13*$D13 -> 99.354839 | AH13: =$E13*AF13 -> 73.92 | AI13: 0.84 | AJ13: =AI13*$D13 -> 99.354839 | AK13: =$E13*AI13 -> 73.92 | AP13: 1.05 | AQ13: =AP13*$D13 -> 124.19355 | AR13: =$E13*AP13 -> 92.4 | AS13: 0.32 | AT13: =AS13*$D13 -> 37.849462 | AU13: =$E13*AS13 -> 28.16 | AV13: 0.67 | AW13: =AV13*$D13 -> 79.247312 | AX13: =$E13*AV13 -> 58.96 | AY13: 0.67 | AZ13: =AY13*$D13 -> 79.247312 | BA13: =$E13*AY13 -> 58.96 | BD13: =(K13+AQ13)/2 -> 136.6129 | BE13: =(L13+AR13)/2 -> 101.64 | BF13: =(N13+AT13)/2 -> 49.086022 | BG13: =(O13+AU13)/2 -> 36.52 | BH13: =(Q13+AW13)/2 -> 96.397849 | BI13: =(R13+AX13)/2 -> 71.72 | BJ13: =(T13+AZ13)/2 -> 96.397849 | BK13: =(U13+BA13)/2 -> 71.72
A14: IV | B14: 30 | C14: =B14*24 -> 720 | D14: =E14*1000/C14 -> 186.11111 | E14: 134 | I14: Nitra | J14: 1.1 | K14: =J14*$D14 -> 204.72222 | L14: =$E14*J14 -> 147.4 | M14: 0.68 | N14: =M14*$D14 -> 126.55556 | O14: =$E14*M14 -> 91.12 | P14: 0.94 | Q14: =P14*$D14 -> 174.94444 | R14: =$E14*P14 -> 125.96 | S14: 0.94 | T14: =S14*$D14 -> 174.94444 | U14: =$E14*S14 -> 125.96 | W14: Nitra | Z14: 0.99 | AA14: =Z14*$D14 -> 184.25 | AB14: =$E14*Z14 -> 132.66 | AC14: 0.33 | AD14: =AC14*$D14 -> 61.416667 | AE14: =$E14*AC14 -> 44.22 | AF14: 0.8 | AG14: =AF14*$D14 -> 148.88889 | AH14: =$E14*AF14 -> 107.2 | AI14: 0.8 | AJ14: =AI14*$D14 -> 148.88889 | AK14: =$E14*AI14 -> 107.2 | AM14: Nitra | AP14: 0.71 | AQ14: =AP14*$D14 -> 132.13889 | AR14: =$E14*AP14 -> 95.14 | AS14: 0.28 | AT14: =AS14*$D14 -> 52.111111 | AU14: =$E14*AS14 -> 37.52 | AV14: 0.59 | AW14: =AV14*$D14 -> 109.80556 | AX14: =$E14*AV14 -> 79.06 | AY14: 0.59 | AZ14: =AY14*$D14 -> 109.80556 | BA14: =$E14*AY14 -> 79.06 | BC14: Nitra | BD14: =(K14+AQ14)/2 -> 168.43056 | BE14: =(L14+AR14)/2 -> 121.27 | BF14: =(N14+AT14)/2 -> 89.333333 | BG14: =(O14+AU14)/2 -> 64.32 | BH14: =(Q14+AW14)/2 -> 142.375 | BI14: =(R14+AX14)/2 -> 102.51 | BJ14: =(T14+AZ14)/2 -> 142.375 | BK14: =(U14+BA14)/2 -> 102.51
A15: V | B15: 31 | C15: =B15*24 -> 744 | D15: =E15*1000/C15 -> 223.11828 | E15: 166 | I15: oblast 1 | J15: 1.01 | K15: =J15*$D15 -> 225.34946 | L15: =$E15*J15 -> 167.66 | M15: 0.79 | N15: =M15*$D15 -> 176.26344 | O15: =$E15*M15 -> 131.14 | P15: 0.94 | Q15: =P15*$D15 -> 209.73118 | R15: =$E15*P15 -> 156.04 | S15: 0.94 | T15: =S15*$D15 -> 209.73118 | U15: =$E15*S15 -> 156.04 | W15: oblast 1 | Z15: 0.84 | AA15: =Z15*$D15 -> 187.41935 | AB15: =$E15*Z15 -> 139.44 | AC15: 0.39 | AD15: =AC15*$D15 -> 87.016129 | AE15: =$E15*AC15 -> 64.74 | AF15: 0.79 | AG15: =AF15*$D15 -> 176.26344 | AH15: =$E15*AF15 -> 131.14 | AI15: 0.79 | AJ15: =AI15*$D15 -> 176.26344 | AK15: =$E15*AI15 -> 131.14 | AM15: oblast 1 | AP15: 0.55 | AQ15: =AP15*$D15 -> 122.71505 | AR15: =$E15*AP15 -> 91.3 | AS15: 0.3 | AT15: =AS15*$D15 -> 66.935484 | AU15: =$E15*AS15 -> 49.8 | AV15: 0.57 | AW15: =AV15*$D15 -> 127.17742 | AX15: =$E15*AV15 -> 94.62 | AY15: 0.57 | AZ15: =AY15*$D15 -> 127.17742 | BA15: =$E15*AY15 -> 94.62 | BC15: oblast 1 | BD15: =(K15+AQ15)/2 -> 174.03226 | BE15: =(L15+AR15)/2 -> 129.48 | BF15: =(N15+AT15)/2 -> 121.59946 | BG15: =(O15+AU15)/2 -> 90.47 | BH15: =(Q15+AW15)/2 -> 168.4543 | BI15: =(R15+AX15)/2 -> 125.33 | BJ15: =(T15+AZ15)/2 -> 168.4543 | BK15: =(U15+BA15)/2 -> 125.33
A16: VI | B16: 30 | C16: =B16*24 -> 720 | D16: =E16*1000/C16 -> 247.22222 | E16: 178 | J16: 0.97 | K16: =J16*$D16 -> 239.80556 | L16: =$E16*J16 -> 172.66 | M16: 0.82 | N16: =M16*$D16 -> 202.72222 | O16: =$E16*M16 -> 145.96 | P16: 0.93 | Q16: =P16*$D16 -> 229.91667 | R16: =$E16*P16 -> 165.54 | S16: 0.93 | T16: =S16*$D16 -> 229.91667 | U16: =$E16*S16 -> 165.54 | Z16: 0.78 | AA16: =Z16*$D16 -> 192.83333 | AB16: =$E16*Z16 -> 138.84 | AC16: 0.45 | AD16: =AC16*$D16 -> 111.25 | AE16: =$E16*AC16 -> 80.1 | AF16: 0.78 | AG16: =AF16*$D16 -> 192.83333 | AH16: =$E16*AF16 -> 138.84 | AI16: 0.78 | AJ16: =AI16*$D16 -> 192.83333 | AK16: =$E16*AI16 -> 138.84 | AP16: 0.49 | AQ16: =AP16*$D16 -> 121.13889 | AR16: =$E16*AP16 -> 87.22 | AS16: 0.31 | AT16: =AS16*$D16 -> 76.638889 | AU16: =$E16*AS16 -> 55.18 | AV16: 0.55 | AW16: =AV16*$D16 -> 135.97222 | AX16: =$E16*AV16 -> 97.9 | AY16: 0.55 | AZ16: =AY16*$D16 -> 135.97222 | BA16: =$E16*AY16 -> 97.9 | BD16: =(K16+AQ16)/2 -> 180.47222 | BE16: =(L16+AR16)/2 -> 129.94 | BF16: =(N16+AT16)/2 -> 139.68056 | BG16: =(O16+AU16)/2 -> 100.57 | BH16: =(Q16+AW16)/2 -> 182.94444 | BI16: =(R16+AX16)/2 -> 131.72 | BJ16: =(T16+AZ16)/2 -> 182.94444 | BK16: =(U16+BA16)/2 -> 131.72
A17: VII | B17: 31 | C17: =B17*24 -> 744 | D17: =E17*1000/C17 -> 229.83871 | E17: 171 | J17: 0.98 | K17: =J17*$D17 -> 225.24194 | L17: =$E17*J17 -> 167.58 | M17: 0.81 | N17: =M17*$D17 -> 186.16935 | O17: =$E17*M17 -> 138.51 | P17: 0.93 | Q17: =P17*$D17 -> 213.75 | R17: =$E17*P17 -> 159.03 | S17: 0.93 | T17: =S17*$D17 -> 213.75 | U17: =$E17*S17 -> 159.03 | Z17: 0.81 | AA17: =Z17*$D17 -> 186.16935 | AB17: =$E17*Z17 -> 138.51 | AC17: 0.42 | AD17: =AC17*$D17 -> 96.532258 | AE17: =$E17*AC17 -> 71.82 | AF17: 0.78 | AG17: =AF17*$D17 -> 179.27419 | AH17: =$E17*AF17 -> 133.38 | AI17: 0.78 | AJ17: =AI17*$D17 -> 179.27419 | AK17: =$E17*AI17 -> 133.38 | AP17: 0.51 | AQ17: =AP17*$D17 -> 117.21774 | AR17: =$E17*AP17 -> 87.21 | AS17: 0.3 | AT17: =AS17*$D17 -> 68.951613 | AU17: =$E17*AS17 -> 51.3 | AV17: 0.55 | AW17: =AV17*$D17 -> 126.41129 | AX17: =$E17*AV17 -> 94.05 | AY17: 0.55 | AZ17: =AY17*$D17 -> 126.41129 | BA17: =$E17*AY17 -> 94.05 | BD17: =(K17+AQ17)/2 -> 171.22984 | BE17: =(L17+AR17)/2 -> 127.395 | BF17: =(N17+AT17)/2 -> 127.56048 | BG17: =(O17+AU17)/2 -> 94.905 | BH17: =(Q17+AW17)/2 -> 170.08065 | BI17: =(R17+AX17)/2 -> 126.54 | BJ17: =(T17+AZ17)/2 -> 170.08065 | BK17: =(U17+BA17)/2 -> 126.54
A18: VIII | B18: 31 | C18: =B18*24 -> 744 | D18: =E18*1000/C18 -> 197.58065 | E18: 147 | J18: 1.05 | K18: =J18*$D18 -> 207.45968 | L18: =$E18*J18 -> 154.35 | M18: 0.73 | N18: =M18*$D18 -> 144.23387 | O18: =$E18*M18 -> 107.31 | P18: 0.93 | Q18: =P18*$D18 -> 183.75 | R18: =$E18*P18 -> 136.71 | S18: 0.93 | T18: =S18*$D18 -> 183.75 | U18: =$E18*S18 -> 136.71 | Z18: 0.91 | AA18: =Z18*$D18 -> 179.79839 | AB18: =$E18*Z18 -> 133.77 | AC18: 0.34 | AD18: =AC18*$D18 -> 67.177419 | AE18: =$E18*AC18 -> 49.98 | AF18: 0.79 | AG18: =AF18*$D18 -> 156.08871 | AH18: =$E18*AF18 -> 116.13 | AI18: 0.79 | AJ18: =AI18*$D18 -> 156.08871 | AK18: =$E18*AI18 -> 116.13 | AP18: 0.62 | AQ18: =AP18*$D18 -> 122.5 | AR18: =$E18*AP18 -> 91.14 | AS18: 0.29 | AT18: =AS18*$D18 -> 57.298387 | AU18: =$E18*AS18 -> 42.63 | AV18: 0.58 | AW18: =AV18*$D18 -> 114.59677 | AX18: =$E18*AV18 -> 85.26 | AY18: 0.58 | AZ18: =AY18*$D18 -> 114.59677 | BA18: =$E18*AY18 -> 85.26 | BD18: =(K18+AQ18)/2 -> 164.97984 | BE18: =(L18+AR18)/2 -> 122.745 | BF18: =(N18+AT18)/2 -> 100.76613 | BG18: =(O18+AU18)/2 -> 74.97 | BH18: =(Q18+AW18)/2 -> 149.17339 | BI18: =(R18+AX18)/2 -> 110.985 | BJ18: =(T18+AZ18)/2 -> 149.17339 | BK18: =(U18+BA18)/2 -> 110.985
A19: IX | B19: 30 | C19: =B19*24 -> 720 | D19: =E19*1000/C19 -> 154.16667 | E19: 111 | J19: 1.18 | K19: =J19*$D19 -> 181.91667 | L19: =$E19*J19 -> 130.98 | M19: 0.58 | N19: =M19*$D19 -> 89.416667 | O19: =$E19*M19 -> 64.38 | P19: 0.95 | Q19: =P19*$D19 -> 146.45833 | R19: =$E19*P19 -> 105.45 | S19: 0.95 | T19: =S19*$D19 -> 146.45833 | U19: =$E19*S19 -> 105.45 | Z19: 1.12 | AA19: =Z19*$D19 -> 172.66667 | AB19: =$E19*Z19 -> 124.32 | AC19: 0.3 | AD19: =AC19*$D19 -> 46.25 | AE19: =$E19*AC19 -> 33.3 | AF19: 0.81 | AG19: =AF19*$D19 -> 124.875 | AH19: =$E19*AF19 -> 89.91 | AI19: 0.81 | AJ19: =AI19*$D19 -> 124.875 | AK19: =$E19*AI19 -> 89.91 | AP19: 0.85 | AQ19: =AP19*$D19 -> 131.04167 | AR19: =$E19*AP19 -> 94.35 | AS19: 0.27 | AT19: =AS19*$D19 -> 41.625 | AU19: =$E19*AS19 -> 29.97 | AV19: 0.6 | AW19: =AV19*$D19 -> 92.5 | AX19: =$E19*AV19 -> 66.6 | AY19: 0.6 | AZ19: =AY19*$D19 -> 92.5 | BA19: =$E19*AY19 -> 66.6 | BD19: =(K19+AQ19)/2 -> 156.47917 | BE19: =(L19+AR19)/2 -> 112.665 | BF19: =(N19+AT19)/2 -> 65.520833 | BG19: =(O19+AU19)/2 -> 47.175 | BH19: =(Q19+AW19)/2 -> 119.47917 | BI19: =(R19+AX19)/2 -> 86.025 | BJ19: =(T19+AZ19)/2 -> 119.47917 | BK19: =(U19+BA19)/2 -> 86.025
A20: X | B20: 31 | C20: =B20*24 -> 744 | D20: =E20*1000/C20 -> 86.021505 | E20: 64 | J20: 1.35 | K20: =J20*$D20 -> 116.12903 | L20: =$E20*J20 -> 86.4 | M20: 0.43 | N20: =M20*$D20 -> 36.989247 | O20: =$E20*M20 -> 27.52 | P20: 0.96 | Q20: =P20*$D20 -> 82.580645 | R20: =$E20*P20 -> 61.44 | S20: 0.96 | T20: =S20*$D20 -> 82.580645 | U20: =$E20*S20 -> 61.44 | Z20: 1.43 | AA20: =Z20*$D20 -> 123.01075 | AB20: =$E20*Z20 -> 91.52 | AC20: 0.33 | AD20: =AC20*$D20 -> 28.387097 | AE20: =$E20*AC20 -> 21.12 | AF20: 0.84 | AG20: =AF20*$D20 -> 72.258065 | AH20: =$E20*AF20 -> 53.76 | AI20: 0.84 | AJ20: =AI20*$D20 -> 72.258065 | AK20: =$E20*AI20 -> 53.76 | AP20: 1.22 | AQ20: =AP20*$D20 -> 104.94624 | AR20: =$E20*AP20 -> 78.08 | AS20: 0.29 | AT20: =AS20*$D20 -> 24.946237 | AU20: =$E20*AS20 -> 18.56 | AV20: 0.64 | AW20: =AV20*$D20 -> 55.053763 | AX20: =$E20*AV20 -> 40.96 | AY20: 0.64 | AZ20: =AY20*$D20 -> 55.053763 | BA20: =$E20*AY20 -> 40.96 | BD20: =(K20+AQ20)/2 -> 110.53763 | BE20: =(L20+AR20)/2 -> 82.24 | BF20: =(N20+AT20)/2 -> 30.967742 | BG20: =(O20+AU20)/2 -> 23.04 | BH20: =(Q20+AW20)/2 -> 68.817204 | BI20: =(R20+AX20)/2 -> 51.2 | BJ20: =(T20+AZ20)/2 -> 68.817204 | BK20: =(U20+BA20)/2 -> 51.2
A21: XI | B21: 30 | C21: =B21*24 -> 720 | D21: =E21*1000/C21 -> 41.666667 | E21: 30 | J21: 1.53 | K21: =J21*$D21 -> 63.75 | L21: =$E21*J21 -> 45.9 | M21: 0.45 | N21: =M21*$D21 -> 18.75 | O21: =$E21*M21 -> 13.5 | P21: 0.98 | Q21: =P21*$D21 -> 40.833333 | R21: =$E21*P21 -> 29.4 | S21: 0.98 | T21: =S21*$D21 -> 40.833333 | U21: =$E21*S21 -> 29.4 | Z21: 1.76 | AA21: =Z21*$D21 -> 73.333333 | AB21: =$E21*Z21 -> 52.8 | AC21: 0.39 | AD21: =AC21*$D21 -> 16.25 | AE21: =$E21*AC21 -> 11.7 | AF21: 0.85 | AG21: =AF21*$D21 -> 35.416667 | AH21: =$E21*AF21 -> 25.5 | AI21: 0.85 | AJ21: =AI21*$D21 -> 35.416667 | AK21: =$E21*AI21 -> 25.5 | AP21: 1.62 | AQ21: =AP21*$D21 -> 67.5 | AR21: =$E21*AP21 -> 48.6 | AS21: 0.35 | AT21: =AS21*$D21 -> 14.583333 | AU21: =$E21*AS21 -> 10.5 | AV21: 0.64 | AW21: =AV21*$D21 -> 26.666667 | AX21: =$E21*AV21 -> 19.2 | AY21: 0.64 | AZ21: =AY21*$D21 -> 26.666667 | BA21: =$E21*AY21 -> 19.2 | BD21: =(K21+AQ21)/2 -> 65.625 | BE21: =(L21+AR21)/2 -> 47.25 | BF21: =(N21+AT21)/2 -> 16.666667 | BG21: =(O21+AU21)/2 -> 12 | BH21: =(Q21+AW21)/2 -> 33.75 | BI21: =(R21+AX21)/2 -> 24.3 | BJ21: =(T21+AZ21)/2 -> 33.75 | BK21: =(U21+BA21)/2 -> 24.3
A22: XII | B22: 31 | C22: =B22*24 -> 744 | D22: =E22*1000/C22 -> 26.88172 | E22: 20 | J22: 1.81 | K22: =J22*$D22 -> 48.655914 | L22: =$E22*J22 -> 36.2 | M22: 0.45 | N22: =M22*$D22 -> 12.096774 | O22: =$E22*M22 -> 9 | P22: 1 | Q22: =P22*$D22 -> 26.88172 | R22: =$E22*P22 -> 20 | S22: 1 | T22: =S22*$D22 -> 26.88172 | U22: =$E22*S22 -> 20 | Z22: 2.23 | AA22: =Z22*$D22 -> 59.946237 | AB22: =$E22*Z22 -> 44.6 | AC22: 0.42 | AD22: =AC22*$D22 -> 11.290323 | AE22: =$E22*AC22 -> 8.4 | AF22: 0.9 | AG22: =AF22*$D22 -> 24.193548 | AH22: =$E22*AF22 -> 18 | AI22: 0.9 | AJ22: =AI22*$D22 -> 24.193548 | AK22: =$E22*AI22 -> 18 | AP22: 2.19 | AQ22: =AP22*$D22 -> 58.870968 | AR22: =$E22*AP22 -> 43.8 | AS22: 0.43 | AT22: =AS22*$D22 -> 11.55914 | AU22: =$E22*AS22 -> 8.6 | AV22: 0.75 | AW22: =AV22*$D22 -> 20.16129 | AX22: =$E22*AV22 -> 15 | AY22: 0.75 | AZ22: =AY22*$D22 -> 20.16129 | BA22: =$E22*AY22 -> 15 | BD22: =(K22+AQ22)/2 -> 53.763441 | BE22: =(L22+AR22)/2 -> 40 | BF22: =(N22+AT22)/2 -> 11.827957 | BG22: =(O22+AU22)/2 -> 8.8 | BH22: =(Q22+AW22)/2 -> 23.521505 | BI22: =(R22+AX22)/2 -> 17.5 | BJ22: =(T22+AZ22)/2 -> 23.521505 | BK22: =(U22+BA22)/2 -> 17.5
A24: month | B24: days | C24: hours | E24: horizontal | J24: South | M24: North | P24: East | S24: West | Z24: South | AC24: North | AF24: East | AI24: West | AP24: South | AS24: North | AV24: East | AY24: West | BD24: South | BF24: North | BH24: East | BJ24: West
D25: W/m2 | E25: kWh/m2 | J25: kvoc | K25: W/m2 | L25: kWh/m2 | M25: kvoc | N25: W/m2 | O25: kWh/m2 | P25: kvoc | Q25: W/m2 | R25: kWh/m2 | S25: kvoc | T25: W/m2 | U25: kWh/m2 | Z25: kvoc | AA25: W/m2 | AB25: kWh/m2 | AC25: kvoc | AD25: W/m2 | AE25: kWh/m2 | AF25: kvoc | AG25: W/m2 | AH25: kWh/m2 | AI25: kvoc | AJ25: W/m2 | AK25: kWh/m2 | AP25: kvoc | AQ25: W/m2 | AR25: kWh/m2 | AS25: kvoc | AT25: W/m2 | AU25: kWh/m2 | AV25: kvoc | AW25: W/m2 | AX25: kWh/m2 | AY25: kvoc | AZ25: W/m2 | BA25: kWh/m2 | BD25: W/m2 | BE25: kWh/m2 | BF25: W/m2 | BG25: kWh/m2 | BH25: W/m2 | BI25: kWh/m2 | BJ25: W/m2 | BK25: kWh/m2
A26: I | B26: 31 | C26: =B26*24 -> 744 | D26: =E26*1000/C26 -> 38.978495 | E26: 29 | J26: 1.61 | K26: =J26*D26 -> 62.755376 | L26: =$E26*J26 -> 46.69 | M26: 0.52 | N26: =M26*D26 -> 20.268817 | O26: =$E26*M26 -> 15.08 | P26: 1 | Q26: =P26*D26 -> 38.978495 | R26: =$E26*P26 -> 29 | S26: 1 | T26: =S26*D26 -> 38.978495 | U26: =$E26*S26 -> 29 | Z26: 1.94 | AA26: =Z26*$D26 -> 75.61828 | AB26: =$E26*Z26 -> 56.26 | AC26: 0.51 | AD26: =AC26*$D26 -> 19.879032 | AE26: =$E26*AC26 -> 14.79 | AF26: 0.95 | AG26: =AF26*$D26 -> 37.02957 | AH26: =$E26*AF26 -> 27.55 | AI26: 0.95 | AJ26: =AI26*$D26 -> 37.02957 | AK26: =$E26*AI26 -> 27.55 | AP26: 1.92 | AQ26: =AP26*$D26 -> 74.83871 | AR26: =$E26*AP26 -> 55.68 | AS26: 0.55 | AT26: =AS26*$D26 -> 21.438172 | AU26: =$E26*AS26 -> 15.95 | AV26: 0.85 | AW26: =AV26*$D26 -> 33.13172 | AX26: =$E26*AV26 -> 24.65 | AY26: 0.85 | AZ26: =AY26*$D26 -> 33.13172 | BA26: =$E26*AY26 -> 24.65 | BD26: =(K26+AQ26)/2 -> 68.797043 | BE26: =(L26+AR26)/2 -> 51.185 | BF26: =(N26+AT26)/2 -> 20.853495 | BG26: =(O26+AU26)/2 -> 15.515 | BH26: =(Q26+AW26)/2 -> 36.055108 | BI26: =(R26+AX26)/2 -> 26.825 | BJ26: =(T26+AZ26)/2 -> 36.055108 | BK26: =(U26+BA26)/2 -> 26.825
A27: II | B27: 28 | C27: =B27*24 -> 672 | D27: =E27*1000/C27 -> 77.380952 | E27: 52 | J27: 1.45 | K27: =J27*D27 -> 112.20238 | L27: =$E27*J27 -> 75.4 | M27: 0.45 | N27: =M27*D27 -> 34.821429 | O27: =$E27*M27 -> 23.4 | P27: 0.98 | Q27: =P27*D27 -> 75.833333 | R27: =$E27*P27 -> 50.96 | S27: 0.98 | T27: =S27*D27 -> 75.833333 | U27: =$E27*S27 -> 50.96 | Z27: 1.64 | AA27: =Z27*$D27 -> 126.90476 | AB27: =$E27*Z27 -> 85.28 | AC27: 0.44 | AD27: =AC27*$D27 -> 34.047619 | AE27: =$E27*AC27 -> 22.88 | AF27: 0.92 | AG27: =AF27*$D27 -> 71.190476 | AH27: =$E27*AF27 -> 47.84 | AI27: 0.92 | AJ27: =AI27*$D27 -> 71.190476 | AK27: =$E27*AI27 -> 47.84 | AP27: 1.54 | AQ27: =AP27*$D27 -> 119.16667 | AR27: =$E27*AP27 -> 80.08 | AS27: 0.47 | AT27: =AS27*$D27 -> 36.369048 | AU27: =$E27*AS27 -> 24.44 | AV27: 0.8 | AW27: =AV27*$D27 -> 61.904762 | AX27: =$E27*AV27 -> 41.6 | AY27: 0.8 | AZ27: =AY27*$D27 -> 61.904762 | BA27: =$E27*AY27 -> 41.6 | BD27: =(K27+AQ27)/2 -> 115.68452 | BE27: =(L27+AR27)/2 -> 77.74 | BF27: =(N27+AT27)/2 -> 35.595238 | BG27: =(O27+AU27)/2 -> 23.92 | BH27: =(Q27+AW27)/2 -> 68.869048 | BI27: =(R27+AX27)/2 -> 46.28 | BJ27: =(T27+AZ27)/2 -> 68.869048 | BK27: =(U27+BA27)/2 -> 46.28
A28: III | B28: 31 | C28: =B28*24 -> 744 | D28: =E28*1000/C28 -> 127.68817 | E28: 95 | J28: 1.25 | K28: =J28*D28 -> 159.61022 | L28: =$E28*J28 -> 118.75 | M28: 0.52 | N28: =M28*D28 -> 66.397849 | O28: =$E28*M28 -> 49.4 | P28: 0.96 | Q28: =P28*D28 -> 122.58065 | R28: =$E28*P28 -> 91.2 | S28: 0.96 | T28: =S28*D28 -> 122.58065 | U28: =$E28*S28 -> 91.2 | Z28: 1.28 | AA28: =Z28*$D28 -> 163.44086 | AB28: =$E28*Z28 -> 121.6 | AC28: 0.35 | AD28: =AC28*$D28 -> 44.69086 | AE28: =$E28*AC28 -> 33.25 | AF28: 0.85 | AG28: =AF28*$D28 -> 108.53495 | AH28: =$E28*AF28 -> 80.75 | AI28: 0.85 | AJ28: =AI28*$D28 -> 108.53495 | AK28: =$E28*AI28 -> 80.75 | AP28: 1.06 | AQ28: =AP28*$D28 -> 135.34946 | AR28: =$E28*AP28 -> 100.7 | AS28: 0.34 | AT28: =AS28*$D28 -> 43.413978 | AU28: =$E28*AS28 -> 32.3 | AV28: 0.67 | AW28: =AV28*$D28 -> 85.551075 | AX28: =$E28*AV28 -> 63.65 | AY28: 0.67 | AZ28: =AY28*$D28 -> 85.551075 | BA28: =$E28*AY28 -> 63.65 | BD28: =(K28+AQ28)/2 -> 147.47984 | BE28: =(L28+AR28)/2 -> 109.725 | BF28: =(N28+AT28)/2 -> 54.905914 | BG28: =(O28+AU28)/2 -> 40.85 | BH28: =(Q28+AW28)/2 -> 104.06586 | BI28: =(R28+AX28)/2 -> 77.425 | BJ28: =(T28+AZ28)/2 -> 104.06586 | BK28: =(U28+BA28)/2 -> 77.425
A29: IV | B29: 30 | C29: =B29*24 -> 720 | D29: =E29*1000/C29 -> 191.66667 | E29: 138 | J29: 1.09 | K29: =J29*D29 -> 208.91667 | L29: =$E29*J29 -> 150.42 | M29: 0.68 | N29: =M29*D29 -> 130.33333 | O29: =$E29*M29 -> 93.84 | P29: 0.94 | Q29: =P29*D29 -> 180.16667 | R29: =$E29*P29 -> 129.72 | S29: 0.94 | T29: =S29*D29 -> 180.16667 | U29: =$E29*S29 -> 129.72 | Z29: 0.99 | AA29: =Z29*$D29 -> 189.75 | AB29: =$E29*Z29 -> 136.62 | AC29: 0.34 | AD29: =AC29*$D29 -> 65.166667 | AE29: =$E29*AC29 -> 46.92 | AF29: 0.81 | AG29: =AF29*$D29 -> 155.25 | AH29: =$E29*AF29 -> 111.78 | AI29: 0.81 | AJ29: =AI29*$D29 -> 155.25 | AK29: =$E29*AI29 -> 111.78 | AP29: 0.72 | AQ29: =AP29*$D29 -> 138 | AR29: =$E29*AP29 -> 99.36 | AS29: 0.3 | AT29: =AS29*$D29 -> 57.5 | AU29: =$E29*AS29 -> 41.4 | AV29: 0.59 | AW29: =AV29*$D29 -> 113.08333 | AX29: =$E29*AV29 -> 81.42 | AY29: 0.59 | AZ29: =AY29*$D29 -> 113.08333 | BA29: =$E29*AY29 -> 81.42 | BC29: Senica | BD29: =(K29+AQ29)/2 -> 173.45833 | BE29: =(L29+AR29)/2 -> 124.89 | BF29: =(N29+AT29)/2 -> 93.916667 | BG29: =(O29+AU29)/2 -> 67.62 | BH29: =(Q29+AW29)/2 -> 146.625 | BI29: =(R29+AX29)/2 -> 105.57 | BJ29: =(T29+AZ29)/2 -> 146.625 | BK29: =(U29+BA29)/2 -> 105.57
A30: V | B30: 31 | C30: =B30*24 -> 744 | D30: =E30*1000/C30 -> 231.1828 | E30: 172 | I30: Senica | J30: 1.01 | K30: =J30*D30 -> 233.49462 | L30: =$E30*J30 -> 173.72 | M30: 0.79 | N30: =M30*D30 -> 182.63441 | O30: =$E30*M30 -> 135.88 | P30: 0.94 | Q30: =P30*D30 -> 217.31183 | R30: =$E30*P30 -> 161.68 | S30: 0.94 | T30: =S30*D30 -> 217.31183 | U30: =$E30*S30 -> 161.68 | W30: Senica | Z30: 0.84 | AA30: =Z30*$D30 -> 194.19355 | AB30: =$E30*Z30 -> 144.48 | AC30: 0.4 | AD30: =AC30*$D30 -> 92.473118 | AE30: =$E30*AC30 -> 68.8 | AF30: 0.79 | AG30: =AF30*$D30 -> 182.63441 | AH30: =$E30*AF30 -> 135.88 | AI30: 0.79 | AJ30: =AI30*$D30 -> 182.63441 | AK30: =$E30*AI30 -> 135.88 | AM30: Senica | AP30: 0.55 | AQ30: =AP30*$D30 -> 127.15054 | AR30: =$E30*AP30 -> 94.6 | AS30: 0.3 | AT30: =AS30*$D30 -> 69.354839 | AU30: =$E30*AS30 -> 51.6 | AV30: 0.56 | AW30: =AV30*$D30 -> 129.46237 | AX30: =$E30*AV30 -> 96.32 | AY30: 0.56 | AZ30: =AY30*$D30 -> 129.46237 | BA30: =$E30*AY30 -> 96.32 | BC30: oblast 2 | BD30: =(K30+AQ30)/2 -> 180.32258 | BE30: =(L30+AR30)/2 -> 134.16 | BF30: =(N30+AT30)/2 -> 125.99462 | BG30: =(O30+AU30)/2 -> 93.74 | BH30: =(Q30+AW30)/2 -> 173.3871 | BI30: =(R30+AX30)/2 -> 129 | BJ30: =(T30+AZ30)/2 -> 173.3871 | BK30: =(U30+BA30)/2 -> 129
A31: VI | B31: 30 | C31: =B31*24 -> 720 | D31: =E31*1000/C31 -> 250 | E31: 180 | I31: oblast 2 | J31: 0.97 | K31: =J31*D31 -> 242.5 | L31: =$E31*J31 -> 174.6 | M31: 0.82 | N31: =M31*D31 -> 205 | O31: =$E31*M31 -> 147.6 | P31: 0.93 | Q31: =P31*D31 -> 232.5 | R31: =$E31*P31 -> 167.4 | S31: 0.93 | T31: =S31*D31 -> 232.5 | U31: =$E31*S31 -> 167.4 | W31: oblast 2 | Z31: 0.78 | AA31: =Z31*$D31 -> 195 | AB31: =$E31*Z31 -> 140.4 | AC31: 0.45 | AD31: =AC31*$D31 -> 112.5 | AE31: =$E31*AC31 -> 81 | AF31: 0.78 | AG31: =AF31*$D31 -> 195 | AH31: =$E31*AF31 -> 140.4 | AI31: 0.78 | AJ31: =AI31*$D31 -> 195 | AK31: =$E31*AI31 -> 140.4 | AM31: oblast 2 | AP31: 0.5 | AQ31: =AP31*$D31 -> 125 | AR31: =$E31*AP31 -> 90 | AS31: 0.32 | AT31: =AS31*$D31 -> 80 | AU31: =$E31*AS31 -> 57.6 | AV31: 0.55 | AW31: =AV31*$D31 -> 137.5 | AX31: =$E31*AV31 -> 99 | AY31: 0.55 | AZ31: =AY31*$D31 -> 137.5 | BA31: =$E31*AY31 -> 99 | BD31: =(K31+AQ31)/2 -> 183.75 | BE31: =(L31+AR31)/2 -> 132.3 | BF31: =(N31+AT31)/2 -> 142.5 | BG31: =(O31+AU31)/2 -> 102.6 | BH31: =(Q31+AW31)/2 -> 185 | BI31: =(R31+AX31)/2 -> 133.2 | BJ31: =(T31+AZ31)/2 -> 185 | BK31: =(U31+BA31)/2 -> 133.2
A32: VII | B32: 31 | C32: =B32*24 -> 744 | D32: =E32*1000/C32 -> 240.5914 | E32: 179 | J32: 0.98 | K32: =J32*D32 -> 235.77957 | L32: =$E32*J32 -> 175.42 | M32: 0.81 | N32: =M32*D32 -> 194.87903 | O32: =$E32*M32 -> 144.99 | P32: 0.93 | Q32: =P32*D32 -> 223.75 | R32: =$E32*P32 -> 166.47 | S32: 0.93 | T32: =S32*D32 -> 223.75 | U32: =$E32*S32 -> 166.47 | Z32: 0.81 | AA32: =Z32*$D32 -> 194.87903 | AB32: =$E32*Z32 -> 144.99 | AC32: 0.42 | AD32: =AC32*$D32 -> 101.04839 | AE32: =$E32*AC32 -> 75.18 | AF32: 0.78 | AG32: =AF32*$D32 -> 187.66129 | AH32: =$E32*AF32 -> 139.62 | AI32: 0.78 | AJ32: =AI32*$D32 -> 187.66129 | AK32: =$E32*AI32 -> 139.62 | AP32: 0.52 | AQ32: =AP32*$D32 -> 125.10753 | AR32: =$E32*AP32 -> 93.08 | AS32: 0.31 | AT32: =AS32*$D32 -> 74.583333 | AU32: =$E32*AS32 -> 55.49 | AV32: 0.55 | AW32: =AV32*$D32 -> 132.32527 | AX32: =$E32*AV32 -> 98.45 | AY32: 0.55 | AZ32: =AY32*$D32 -> 132.32527 | BA32: =$E32*AY32 -> 98.45 | BD32: =(K32+AQ32)/2 -> 180.44355 | BE32: =(L32+AR32)/2 -> 134.25 | BF32: =(N32+AT32)/2 -> 134.73118 | BG32: =(O32+AU32)/2 -> 100.24 | BH32: =(Q32+AW32)/2 -> 178.03763 | BI32: =(R32+AX32)/2 -> 132.46 | BJ32: =(T32+AZ32)/2 -> 178.03763 | BK32: =(U32+BA32)/2 -> 132.46
A33: VIII | B33: 31 | C33: =B33*24 -> 744 | D33: =E33*1000/C33 -> 208.33333 | E33: 155 | J33: 1.04 | K33: =J33*D33 -> 216.66667 | L33: =$E33*J33 -> 161.2 | M33: 0.73 | N33: =M33*D33 -> 152.08333 | O33: =$E33*M33 -> 113.15 | P33: 0.94 | Q33: =P33*D33 -> 195.83333 | R33: =$E33*P33 -> 145.7 | S33: 0.94 | T33: =S33*D33 -> 195.83333 | U33: =$E33*S33 -> 145.7 | Z33: 0.91 | AA33: =Z33*$D33 -> 189.58333 | AB33: =$E33*Z33 -> 141.05 | AC33: 0.35 | AD33: =AC33*$D33 -> 72.916667 | AE33: =$E33*AC33 -> 54.25 | AF33: 0.79 | AG33: =AF33*$D33 -> 164.58333 | AH33: =$E33*AF33 -> 122.45 | AI33: 0.79 | AJ33: =AI33*$D33 -> 164.58333 | AK33: =$E33*AI33 -> 122.45 | AP33: 0.62 | AQ33: =AP33*$D33 -> 129.16667 | AR33: =$E33*AP33 -> 96.1 | AS33: 0.3 | AT33: =AS33*$D33 -> 62.5 | AU33: =$E33*AS33 -> 46.5 | AV33: 0.57 | AW33: =AV33*$D33 -> 118.75 | AX33: =$E33*AV33 -> 88.35 | AY33: 0.57 | AZ33: =AY33*$D33 -> 118.75 | BA33: =$E33*AY33 -> 88.35 | BD33: =(K33+AQ33)/2 -> 172.91667 | BE33: =(L33+AR33)/2 -> 128.65 | BF33: =(N33+AT33)/2 -> 107.29167 | BG33: =(O33+AU33)/2 -> 79.825 | BH33: =(Q33+AW33)/2 -> 157.29167 | BI33: =(R33+AX33)/2 -> 117.025 | BJ33: =(T33+AZ33)/2 -> 157.29167 | BK33: =(U33+BA33)/2 -> 117.025
A34: IX | B34: 30 | C34: =B34*24 -> 720 | D34: =E34*1000/C34 -> 166.66667 | E34: 120 | J34: 1.17 | K34: =J34*D34 -> 195 | L34: =$E34*J34 -> 140.4 | M34: 0.59 | N34: =M34*D34 -> 98.333333 | O34: =$E34*M34 -> 70.8 | P34: 0.95 | Q34: =P34*D34 -> 158.33333 | R34: =$E34*P34 -> 114 | S34: 0.95 | T34: =S34*D34 -> 158.33333 | U34: =$E34*S34 -> 114 | Z34: 1.11 | AA34: =Z34*$D34 -> 185 | AB34: =$E34*Z34 -> 133.2 | AC34: 0.31 | AD34: =AC34*$D34 -> 51.666667 | AE34: =$E34*AC34 -> 37.2 | AF34: 0.81 | AG34: =AF34*$D34 -> 135 | AH34: =$E34*AF34 -> 97.2 | AI34: 0.81 | AJ34: =AI34*$D34 -> 135 | AK34: =$E34*AI34 -> 97.2 | AP34: 0.85 | AQ34: =AP34*$D34 -> 141.66667 | AR34: =$E34*AP34 -> 102 | AS34: 0.28 | AT34: =AS34*$D34 -> 46.666667 | AU34: =$E34*AS34 -> 33.6 | AV34: 0.6 | AW34: =AV34*$D34 -> 100 | AX34: =$E34*AV34 -> 72 | AY34: 0.6 | AZ34: =AY34*$D34 -> 100 | BA34: =$E34*AY34 -> 72 | BD34: =(K34+AQ34)/2 -> 168.33333 | BE34: =(L34+AR34)/2 -> 121.2 | BF34: =(N34+AT34)/2 -> 72.5 | BG34: =(O34+AU34)/2 -> 52.2 | BH34: =(Q34+AW34)/2 -> 129.16667 | BI34: =(R34+AX34)/2 -> 93 | BJ34: =(T34+AZ34)/2 -> 129.16667 | BK34: =(U34+BA34)/2 -> 93
A35: X | B35: 31 | C35: =B35*24 -> 744 | D35: =E35*1000/C35 -> 98.11828 | E35: 73 | J35: 1.33 | K35: =J35*D35 -> 130.49731 | L35: =$E35*J35 -> 97.09 | M35: 0.45 | N35: =M35*D35 -> 44.153226 | O35: =$E35*M35 -> 32.85 | P35: 0.96 | Q35: =P35*D35 -> 94.193548 | R35: =$E35*P35 -> 70.08 | S35: 0.96 | T35: =S35*D35 -> 94.193548 | U35: =$E35*S35 -> 70.08 | Z35: 1.4 | AA35: =Z35*$D35 -> 137.36559 | AB35: =$E35*Z35 -> 102.2 | AC35: 0.34 | AD35: =AC35*$D35 -> 33.360215 | AE35: =$E35*AC35 -> 24.82 | AF35: 0.84 | AG35: =AF35*$D35 -> 82.419355 | AH35: =$E35*AF35 -> 61.32 | AI35: 0.84 | AJ35: =AI35*$D35 -> 82.419355 | AK35: =$E35*AI35 -> 61.32 | AP35: 1.19 | AQ35: =AP35*$D35 -> 116.76075 | AR35: =$E35*AP35 -> 86.87 | AS35: 0.3 | AT35: =AS35*$D35 -> 29.435484 | AU35: =$E35*AS35 -> 21.9 | AV35: 0.63 | AW35: =AV35*$D35 -> 61.814516 | AX35: =$E35*AV35 -> 45.99 | AY35: 0.63 | AZ35: =AY35*$D35 -> 61.814516 | BA35: =$E35*AY35 -> 45.99 | BD35: =(K35+AQ35)/2 -> 123.62903 | BE35: =(L35+AR35)/2 -> 91.98 | BF35: =(N35+AT35)/2 -> 36.794355 | BG35: =(O35+AU35)/2 -> 27.375 | BH35: =(Q35+AW35)/2 -> 78.004032 | BI35: =(R35+AX35)/2 -> 58.035 | BJ35: =(T35+AZ35)/2 -> 78.004032 | BK35: =(U35+BA35)/2 -> 58.035
A36: XI | B36: 30 | C36: =B36*24 -> 720 | D36: =E36*1000/C36 -> 47.222222 | E36: 34 | J36: 1.52 | K36: =J36*D36 -> 71.777778 | L36: =$E36*J36 -> 51.68 | M36: 0.47 | N36: =M36*D36 -> 22.194444 | O36: =$E36*M36 -> 15.98 | P36: 0.97 | Q36: =P36*D36 -> 45.805556 | R36: =$E36*P36 -> 32.98 | S36: 0.97 | T36: =S36*D36 -> 45.805556 | U36: =$E36*S36 -> 32.98 | Z36: 1.75 | AA36: =Z36*$D36 -> 82.638889 | AB36: =$E36*Z36 -> 59.5 | AC36: 0.4 | AD36: =AC36*$D36 -> 18.888889 | AE36: =$E36*AC36 -> 13.6 | AF36: 0.86 | AG36: =AF36*$D36 -> 40.611111 | AH36: =$E36*AF36 -> 29.24 | AI36: 0.86 | AJ36: =AI36*$D36 -> 40.611111 | AK36: =$E36*AI36 -> 29.24 | AP36: 1.62 | AQ36: =AP36*$D36 -> 76.5 | AR36: =$E36*AP36 -> 55.08 | AS36: 0.37 | AT36: =AS36*$D36 -> 17.472222 | AU36: =$E36*AS36 -> 12.58 | AV36: 0.65 | AW36: =AV36*$D36 -> 30.694444 | AX36: =$E36*AV36 -> 22.1 | AY36: 0.65 | AZ36: =AY36*$D36 -> 30.694444 | BA36: =$E36*AY36 -> 22.1 | BD36: =(K36+AQ36)/2 -> 74.138889 | BE36: =(L36+AR36)/2 -> 53.38 | BF36: =(N36+AT36)/2 -> 19.833333 | BG36: =(O36+AU36)/2 -> 14.28 | BH36: =(Q36+AW36)/2 -> 38.25 | BI36: =(R36+AX36)/2 -> 27.54 | BJ36: =(T36+AZ36)/2 -> 38.25 | BK36: =(U36+BA36)/2 -> 27.54
A37: XII | B37: 31 | C37: =B37*24 -> 744 | D37: =E37*1000/C37 -> 40.322581 | E37: 30 | J37: 1.76 | K37: =J37*D37 -> 70.967742 | L37: =$E37*J37 -> 52.8 | M37: 0.48 | N37: =M37*D37 -> 19.354839 | O37: =$E37*M37 -> 14.4 | P37: 0.99 | Q37: =P37*D37 -> 39.919355 | R37: =$E37*P37 -> 29.7 | S37: 0.99 | T37: =S37*D37 -> 39.919355 | U37: =$E37*S37 -> 29.7 | Z37: 2.15 | AA37: =Z37*$D37 -> 86.693548 | AB37: =$E37*Z37 -> 64.5 | AC37: 0.46 | AD37: =AC37*$D37 -> 18.548387 | AE37: =$E37*AC37 -> 13.8 | AF37: 0.9 | AG37: =AF37*$D37 -> 36.290323 | AH37: =$E37*AF37 -> 27 | AI37: 0.9 | AJ37: =AI37*$D37 -> 36.290323 | AK37: =$E37*AI37 -> 27 | AP37: 2.19 | AQ37: =AP37*$D37 -> 88.306452 | AR37: =$E37*AP37 -> 65.7 | AS37: 0.46 | AT37: =AS37*$D37 -> 18.548387 | AU37: =$E37*AS37 -> 13.8 | AV37: 0.77 | AW37: =AV37*$D37 -> 31.048387 | AX37: =$E37*AV37 -> 23.1 | AY37: 0.77 | AZ37: =AY37*$D37 -> 31.048387 | BA37: =$E37*AY37 -> 23.1 | BD37: =(K37+AQ37)/2 -> 79.637097 | BE37: =(L37+AR37)/2 -> 59.25 | BF37: =(N37+AT37)/2 -> 18.951613 | BG37: =(O37+AU37)/2 -> 14.1 | BH37: =(Q37+AW37)/2 -> 35.483871 | BI37: =(R37+AX37)/2 -> 26.4 | BJ37: =(T37+AZ37)/2 -> 35.483871 | BK37: =(U37+BA37)/2 -> 26.4
A39: month | B39: days | C39: hours | E39: horizontal | J39: South | M39: North | P39: East | S39: West | Z39: South | AC39: North | AF39: East | AI39: West | AP39: South | AS39: North | AV39: East | AY39: West | BD39: South | BF39: North | BH39: East | BJ39: West
D40: W/m2 | E40: kWh/m2 | J40: kvoc | K40: W/m2 | L40: kWh/m2 | M40: kvoc | N40: W/m2 | O40: kWh/m2 | P40: kvoc | Q40: W/m2 | R40: kWh/m2 | S40: kvoc | T40: W/m2 | U40: kWh/m2 | Z40: kvoc | AA40: W/m2 | AB40: kWh/m2 | AC40: kvoc | AD40: W/m2 | AE40: kWh/m2 | AF40: kvoc | AG40: W/m2 | AH40: kWh/m2 | AI40: kvoc | AJ40: W/m2 | AK40: kWh/m2 | AP40: kvoc | AQ40: W/m2 | AR40: kWh/m2 | AS40: kvoc | AT40: W/m2 | AU40: kWh/m2 | AV40: kvoc | AW40: W/m2 | AX40: kWh/m2 | AY40: kvoc | AZ40: W/m2 | BA40: kWh/m2 | BD40: W/m2 | BE40: kWh/m2 | BF40: W/m2 | BG40: kWh/m2 | BH40: W/m2 | BI40: kWh/m2 | BJ40: W/m2 | BK40: kWh/m2
A41: I | B41: 31 | C41: =B41*24 -> 744 | D41: =E41*1000/C41 -> 34.946237 | E41: 26 | J41: 1.61 | K41: =J41*D41 -> 56.263441 | L41: =$E41*J41 -> 41.86 | M41: 0.52 | N41: =M41*D41 -> 18.172043 | O41: =$E41*M41 -> 13.52 | P41: 1 | Q41: =P41*D41 -> 34.946237 | R41: =$E41*P41 -> 26 | S41: 1 | T41: =S41*D41 -> 34.946237 | U41: =$E41*S41 -> 26 | Z41: 1.94 | AA41: =Z41*$D41 -> 67.795699 | AB41: =$E41*Z41 -> 50.44 | AC41: 0.51 | AD41: =AC41*$D41 -> 17.822581 | AE41: =$E41*AC41 -> 13.26 | AF41: 0.95 | AG41: =AF41*$D41 -> 33.198925 | AH41: =$E41*AF41 -> 24.7 | AI41: 0.95 | AJ41: =AI41*$D41 -> 33.198925 | AK41: =$E41*AI41 -> 24.7 | AP41: 1.92 | AQ41: =AP41*$D41 -> 67.096774 | AR41: =$E41*AP41 -> 49.92 | AS41: 0.55 | AT41: =AS41*$D41 -> 19.22043 | AU41: =$E41*AS41 -> 14.3 | AV41: 0.85 | AW41: =AV41*$D41 -> 29.704301 | AX41: =$E41*AV41 -> 22.1 | AY41: 0.85 | AZ41: =AY41*$D41 -> 29.704301 | BA41: =$E41*AY41 -> 22.1 | BD41: =(K41+AQ41)/2 -> 61.680108 | BE41: =(L41+AR41)/2 -> 45.89 | BF41: =(N41+AT41)/2 -> 18.696237 | BG41: =(O41+AU41)/2 -> 13.91 | BH41: =(Q41+AW41)/2 -> 32.325269 | BI41: =(R41+AX41)/2 -> 24.05 | BJ41: =(T41+AZ41)/2 -> 32.325269 | BK41: =(U41+BA41)/2 -> 24.05
A42: II | B42: 28 | C42: =B42*24 -> 672 | D42: =E42*1000/C42 -> 74.404762 | E42: 50 | J42: 1.45 | K42: =J42*D42 -> 107.8869 | L42: =$E42*J42 -> 72.5 | M42: 0.45 | N42: =M42*D42 -> 33.482143 | O42: =$E42*M42 -> 22.5 | P42: 0.98 | Q42: =P42*D42 -> 72.916667 | R42: =$E42*P42 -> 49 | S42: 0.98 | T42: =S42*D42 -> 72.916667 | U42: =$E42*S42 -> 49 | Z42: 1.64 | AA42: =Z42*$D42 -> 122.02381 | AB42: =$E42*Z42 -> 82 | AC42: 0.44 | AD42: =AC42*$D42 -> 32.738095 | AE42: =$E42*AC42 -> 22 | AF42: 0.92 | AG42: =AF42*$D42 -> 68.452381 | AH42: =$E42*AF42 -> 46 | AI42: 0.92 | AJ42: =AI42*$D42 -> 68.452381 | AK42: =$E42*AI42 -> 46 | AP42: 1.54 | AQ42: =AP42*$D42 -> 114.58333 | AR42: =$E42*AP42 -> 77 | AS42: 0.47 | AT42: =AS42*$D42 -> 34.970238 | AU42: =$E42*AS42 -> 23.5 | AV42: 0.8 | AW42: =AV42*$D42 -> 59.52381 | AX42: =$E42*AV42 -> 40 | AY42: 0.8 | AZ42: =AY42*$D42 -> 59.52381 | BA42: =$E42*AY42 -> 40 | BD42: =(K42+AQ42)/2 -> 111.23512 | BE42: =(L42+AR42)/2 -> 74.75 | BF42: =(N42+AT42)/2 -> 34.22619 | BG42: =(O42+AU42)/2 -> 23 | BH42: =(Q42+AW42)/2 -> 66.220238 | BI42: =(R42+AX42)/2 -> 44.5 | BJ42: =(T42+AZ42)/2 -> 66.220238 | BK42: =(U42+BA42)/2 -> 44.5
A43: III | B43: 31 | C43: =B43*24 -> 744 | D43: =E43*1000/C43 -> 120.96774 | E43: 90 | J43: 1.25 | K43: =J43*D43 -> 151.20968 | L43: =$E43*J43 -> 112.5 | M43: 0.52 | N43: =M43*D43 -> 62.903226 | O43: =$E43*M43 -> 46.8 | P43: 0.96 | Q43: =P43*D43 -> 116.12903 | R43: =$E43*P43 -> 86.4 | S43: 0.96 | T43: =S43*D43 -> 116.12903 | U43: =$E43*S43 -> 86.4 | Z43: 1.28 | AA43: =Z43*$D43 -> 154.83871 | AB43: =$E43*Z43 -> 115.2 | AC43: 0.35 | AD43: =AC43*$D43 -> 42.33871 | AE43: =$E43*AC43 -> 31.5 | AF43: 0.85 | AG43: =AF43*$D43 -> 102.82258 | AH43: =$E43*AF43 -> 76.5 | AI43: 0.85 | AJ43: =AI43*$D43 -> 102.82258 | AK43: =$E43*AI43 -> 76.5 | AP43: 1.06 | AQ43: =AP43*$D43 -> 128.22581 | AR43: =$E43*AP43 -> 95.4 | AS43: 0.34 | AT43: =AS43*$D43 -> 41.129032 | AU43: =$E43*AS43 -> 30.6 | AV43: 0.67 | AW43: =AV43*$D43 -> 81.048387 | AX43: =$E43*AV43 -> 60.3 | AY43: 0.67 | AZ43: =AY43*$D43 -> 81.048387 | BA43: =$E43*AY43 -> 60.3 | BD43: =(K43+AQ43)/2 -> 139.71774 | BE43: =(L43+AR43)/2 -> 103.95 | BF43: =(N43+AT43)/2 -> 52.016129 | BG43: =(O43+AU43)/2 -> 38.7 | BH43: =(Q43+AW43)/2 -> 98.58871 | BI43: =(R43+AX43)/2 -> 73.35 | BJ43: =(T43+AZ43)/2 -> 98.58871 | BK43: =(U43+BA43)/2 -> 73.35
A44: IV | B44: 30 | C44: =B44*24 -> 720 | D44: =E44*1000/C44 -> 186.11111 | E44: 134 | I44: Topolcany | J44: 1.09 | K44: =J44*D44 -> 202.86111 | L44: =$E44*J44 -> 146.06 | M44: 0.68 | N44: =M44*D44 -> 126.55556 | O44: =$E44*M44 -> 91.12 | P44: 0.94 | Q44: =P44*D44 -> 174.94444 | R44: =$E44*P44 -> 125.96 | S44: 0.94 | T44: =S44*D44 -> 174.94444 | U44: =$E44*S44 -> 125.96 | W44: Topolcany | Z44: 0.99 | AA44: =Z44*$D44 -> 184.25 | AB44: =$E44*Z44 -> 132.66 | AC44: 0.34 | AD44: =AC44*$D44 -> 63.277778 | AE44: =$E44*AC44 -> 45.56 | AF44: 0.81 | AG44: =AF44*$D44 -> 150.75 | AH44: =$E44*AF44 -> 108.54 | AI44: 0.81 | AJ44: =AI44*$D44 -> 150.75 | AK44: =$E44*AI44 -> 108.54 | AM44: Topolcany | AP44: 0.72 | AQ44: =AP44*$D44 -> 134 | AR44: =$E44*AP44 -> 96.48 | AS44: 0.3 | AT44: =AS44*$D44 -> 55.833333 | AU44: =$E44*AS44 -> 40.2 | AV44: 0.59 | AW44: =AV44*$D44 -> 109.80556 | AX44: =$E44*AV44 -> 79.06 | AY44: 0.59 | AZ44: =AY44*$D44 -> 109.80556 | BA44: =$E44*AY44 -> 79.06 | BC44: Topolcany | BD44: =(K44+AQ44)/2 -> 168.43056 | BE44: =(L44+AR44)/2 -> 121.27 | BF44: =(N44+AT44)/2 -> 91.194444 | BG44: =(O44+AU44)/2 -> 65.66 | BH44: =(Q44+AW44)/2 -> 142.375 | BI44: =(R44+AX44)/2 -> 102.51 | BJ44: =(T44+AZ44)/2 -> 142.375 | BK44: =(U44+BA44)/2 -> 102.51
A45: V | B45: 31 | C45: =B45*24 -> 744 | D45: =E45*1000/C45 -> 228.49462 | E45: 170 | I45: oblast 2 | J45: 1.01 | K45: =J45*D45 -> 230.77957 | L45: =$E45*J45 -> 171.7 | M45: 0.79 | N45: =M45*D45 -> 180.51075 | O45: =$E45*M45 -> 134.3 | P45: 0.94 | Q45: =P45*D45 -> 214.78495 | R45: =$E45*P45 -> 159.8 | S45: 0.94 | T45: =S45*D45 -> 214.78495 | U45: =$E45*S45 -> 159.8 | W45: oblast 2 | Z45: 0.84 | AA45: =Z45*$D45 -> 191.93548 | AB45: =$E45*Z45 -> 142.8 | AC45: 0.4 | AD45: =AC45*$D45 -> 91.397849 | AE45: =$E45*AC45 -> 68 | AF45: 0.79 | AG45: =AF45*$D45 -> 180.51075 | AH45: =$E45*AF45 -> 134.3 | AI45: 0.79 | AJ45: =AI45*$D45 -> 180.51075 | AK45: =$E45*AI45 -> 134.3 | AM45: oblast 2 | AP45: 0.55 | AQ45: =AP45*$D45 -> 125.67204 | AR45: =$E45*AP45 -> 93.5 | AS45: 0.3 | AT45: =AS45*$D45 -> 68.548387 | AU45: =$E45*AS45 -> 51 | AV45: 0.56 | AW45: =AV45*$D45 -> 127.95699 | AX45: =$E45*AV45 -> 95.2 | AY45: 0.56 | AZ45: =AY45*$D45 -> 127.95699 | BA45: =$E45*AY45 -> 95.2 | BC45: oblast 2 | BD45: =(K45+AQ45)/2 -> 178.22581 | BE45: =(L45+AR45)/2 -> 132.6 | BF45: =(N45+AT45)/2 -> 124.52957 | BG45: =(O45+AU45)/2 -> 92.65 | BH45: =(Q45+AW45)/2 -> 171.37097 | BI45: =(R45+AX45)/2 -> 127.5 | BJ45: =(T45+AZ45)/2 -> 171.37097 | BK45: =(U45+BA45)/2 -> 127.5
...

Sheet Trieda budovy
A1: Tab. č.3
A2: Vstupné údaje pre dynamické veličiny podľa STN EN ISO 13790
A3: Trieda budovy | B3: Vnútorná tepelná kapacita
B4: c | C4: Cm = c*Ab | D4: Cm = c*Ab/1000
B5: (J/(K.m2) | C5: (J/K) | D5: (kJ/K)
A6: Veľmi ľahká | B6: 80000 | C6: =B6*Legenda!A10 -> 0 | D6: =C6/1000 -> 0
A7: Ľahká | B7: 110000 | C7: =B7*Legenda!A10 -> 0 | D7: =C7/1000 -> 0
A8: Stredne ťažká | B8: 165000 | C8: =B8*Legenda!A10 -> 0 | D8: =C8/1000 -> 0
A9: Ťažká | B9: 260000 | C9: =B9*Legenda!A10 -> 0 | D9: =C9/1000 -> 0
A10: Veľmi ťažká | B10: 370000 | C10: =B10*Legenda!A10 -> 0 | D10: =C10/1000 -> 0
