Workbook
Name konštrukcie: [1]zoznamy!$A$3:$A$10
Name materialy: [1]zoznamy!$F$3:$F$65541
Name odpory: [1]zoznamy!$C$3:$C$6
Name systém: [1]zoznamy!$AB$2:$AB$3

Sheet VstupneUdaje
A1: posudenie obalovych konstrukcii R, U podla STN 73 0540-2,3 | G1: vhovuje | H1: nevyhovuje | L1: Kategória budovy | N1: Číselník DPH | BE1: Priemerný tepelný výkon vnútorných zdrojov tepla podľa STN 73 0540-2 | BN1: Osvetlenie
B2: sucinitel pre podlahu STN EN ISO 13 370 | L2: Rodinné domy | N2: áno | O2: 1.2 | BE2: bytové domy | BI2: 5 | BJ2: W/m2 | BO2: Merný výkon | BP2: Merný výkon | BQ2: CENA bez DPH (€) | BR2: merná cena bez DPH (€) | BT2: Životnosť
B3: sirenie vlhkosti? | L3: Bytové domy | N3: nie | O3: 1 | BE3: rodinné domy | BI3: 4 | BJ3: W/m2 | BO3: lm/W | BP3: v rozsahu | BQ3: € | BR3: fix €/ks | BS3: var. €/W | BT3: h
L4: Administratívne budovy | BE4: ostatné | BI4: 6 | BJ4: W/m2 | BN4: obyčajná žiarovka | BO4: 13 | BP4: 6 – 15 | BQ4: 0.27 | BR4: 0.66 | BS4: 0.01 | BT4: 1000
L5: Budovy škôl a školských zariadení | BN5: halogénová žiarovka | BO5: 15 | BP5: 12 –17 | BQ5: 4.32 | BR5: 2.66 | BS5: 0.03 | BT5: 3000
L6: Budovy nemocníc | BN6: LED žiarovka | BO6: 85 | BP6: 60 – 90 | BQ6: 23.24 | BR6: 11.62 | BS6: 0.66 | BT6: 50000
L7: Budovy hotelov a reštaurácií | BN7: LED žiarovka + nové svietidlo | BO7: 85 | BP7: 60 – 90 | BQ7: 120 | BR7: =33+10 -> 43 | BS7: 1.7 | BT7: 50000
L8: Športové haly a iné budovy určené na šport | BN8: LED žiarovka + nové svietidlo + pohybový senzor | BO8: 85 | BP8: 60 – 90 | BR8: =50+10 -> 60 | BS8: 1.7 | BT8: 50000
L9: Budovy pre veľkoobchodné a maloobchodné služby | BN9: LED svetelná trubica + nové svietidlo | BO9: 95 | BP9: 90 – 100 | BQ9: 165 | BR9: =115+10 -> 125 | BS9: 0.5 | BT9: 50000
L10: Výrobné haly a priemyselné budovy | BN10: lineárna žiarivka T8 + klasický predradník | BO10: 60 | BP10: 55 – 74 | BQ10: 1.83 | BR10: 0 | BS10: 0.03 | BT10: 8000
BN11: lineárna žiarivka T8 + elektronický predradník | BO11: 80 | BP11: 75 – 90 | BQ11: 0 | BR11: 27.22 | BS11: 0.03 | BT11: 15000
L12: Klimatické údaje | Q12: Klimatické podmienky podľa STN EN ISO 13790 | BE12: Normalizovaný počet dennostupňov | BN12: lineárna žiarivka T8 + elektronický predradník + nové svietidlo | BO12: 80 | BP12: 75 – 90 | BR12: =32+10 -> 42 | BS12: 0.25 | BT12: 15000
N13: Normalizované hodnotenie | O13: Upravené hodnotenie | Q13: Mesiac: | R13: SPOLU | S13: Január | V13: Február | Y13: Marec | AB13: Apríl | AE13: Máj | AH13: Jún | AK13: Júl | AN13: August | AQ13: September | AT13: Október | AW13: Novebmer | AZ13: December | BE13: Mesiac | BF13: d (dni) | BG13: Vnútorná teplota (°C) | BH13: Vonkajšia priemerná (°C) | BI13: D (K.deň) | BJ13: xi | BN13: lineárna žiarivka T5 + elektronický predradník + nové svietidlo | BO13: 95 | BP13: 90 – 107 | BQ13: 1.83 | BR13: =30+10 -> 40 | BS13: 0.35 | BT13: 16000
L14: Vonkajšia výpočtová teplota (oC): | M14: qe | N14: -15 | O14: =VLOOKUP(#REF!,Dennostupne!B3:E81,4,FALSE) -> #REF! | Q14: VO : | R14: =SUM(S17:BB17) -> 4432.4 | S14: 31 | V14: 28 | Y14: 31 | AB14: 30 | AE14: 5 | AH14: 0 | AK14: 0 | AN14: 0 | AQ14: 5 | AT14: 31 | AW14: 30 | AZ14: 31 | BC14: dni | BE14: Január | BF14: 31 | BG14: 20 | BH14: -1.8 | BI14: =BF14*(BG14-BH14) -> 675.8 | BJ14: =BI14*0.024 -> 16.2192 | BN14: kompaktná žiarivka | BO14: 50 | BP14: 40 – 87 | BQ14: 4.65 | BR14: 4.32 | BS14: 0.03 | BT14: 6000
L15: Veterná oblasť, rýchlosť vetra (ms-1) | M15: v | N15: - | O15: =VLOOKUP(#REF!,Dennostupne!B3:F81,5,FALSE) -> #REF! | Q15: prac./voľno | R15: =SUM(S18:BB18) -> 720 | S15: =S14-U15 -> 22.142857 | U15: =S14/7*2 -> 8.8571429 | V15: =V14-X15 -> 20 | X15: =V14/7*2 -> 8 | Y15: =Y14-AA15 -> 22.142857 | AA15: =Y14/7*2 -> 8.8571429 | AB15: =AB14-AD15 -> 21.428571 | AD15: =AB14/7*2 -> 8.5714286 | AE15: =AE14-AG15 -> 3.5714286 | AG15: =AE14/7*2 -> 1.4285714 | AH15: =AH14-AJ15 -> 0 | AJ15: =AH14/7*2 -> 0 | AK15: =AK14-AM15 -> 0 | AM15: =AK14/7*2 -> 0 | AN15: =AN14-AP15 -> 0 | AP15: =AN14/7*2 -> 0 | AQ15: =AQ14-AS15 -> 3.5714286 | AS15: =AQ14/7*2 -> 1.4285714 | AT15: =AT14-AV15 -> 22.142857 | AV15: =AT14/7*2 -> 8.8571429 | AW15: =AW14-AY15 -> 21.428571 | AY15: =AW14/7*2 -> 8.5714286 | AZ15: =AZ14-BB15 -> 22.142857 | BB15: =AZ14/7*2 -> 8.8571429 | BC15: dní | BE15: Február | BF15: 28 | BG15: 20 | BH15: 0.4 | BI15: =BF15*(BG15-BH15) -> 548.8 | BJ15: =BI15*0.024 -> 13.1712 | BN15: sodíková výbojka nízkotlaká | BO15: 150 | BP15: 100 – 210 | BQ15: 34.85 | BR15: 66.39 | BS15: 0.53 | BT15: 14000
L16: Vnútorná výpočtová teplota (oC): | M16: qi | N16: 20 | O16: 20 | Q16: Norm/útlm: | S16: 16 | T16: =24-S16 -> 8 | U16: 24 | V16: 16 | W16: =24-V16 -> 8 | X16: 24 | Y16: 16 | Z16: =24-Y16 -> 8 | AA16: 24 | AB16: 16 | AC16: =24-AB16 -> 8 | AD16: 24 | AE16: 16 | AF16: =24-AE16 -> 8 | AG16: 24 | AH16: 16 | AI16: =24-AH16 -> 8 | AJ16: 24 | AK16: 16 | AL16: =24-AK16 -> 8 | AM16: 24 | AN16: 16 | AO16: =24-AN16 -> 8 | AP16: 24 | AQ16: 16 | AR16: =24-AQ16 -> 8 | AS16: 24 | AT16: 16 | AU16: =24-AT16 -> 8 | AV16: 24 | AW16: 16 | AX16: =24-AW16 -> 8 | AY16: 24 | AZ16: 16 | BA16: =24-AZ16 -> 8 | BB16: 24 | BC16: hod | BE16: Marec | BF16: 31 | BG16: 20 | BH16: 4.6 | BI16: =BF16*(BG16-BH16) -> 477.4 | BJ16: =BI16*0.024 -> 11.4576 | BN16: sodíková výbojka vysokotlaková | BO16: 120 | BP16: 100 – 140 | BQ16: 18.26 | BR16: 116.18 | BS16: 0.18 | BT16: 25000
L17: Priemerná vonkajšia teplota vykurovacieho obdobia (oC): | M17: qae | N17: 3.86 | O17: =U8 -> 0 | Q17: D° : | R17: =SUM(S17:BB17) -> 4432.4 | S17: =(S18-S19)*S15/24*S16 -> 379.38095 | T17: =(T18-T19)*S15/24*T16 -> 189.69048 | U17: =(U18-U19)*U15/24*U16 -> 227.62857 | V17: =(V18-V19)*V15/24*V16 -> 321.33333 | W17: =(W18-W19)*V15/24*W16 -> 160.66667 | X17: =(X18-X19)*X15/24*X16 -> 192.8 | Y17: =(Y18-Y19)*Y15/24*Y16 -> 301.14286 | Z17: =(Z18-Z19)*Y15/24*Z16 -> 150.57143 | AA17: =(AA18-AA19)*AA15/24*AA16 -> 180.68571 | AB17: =(AB18-AB19)*AB15/24*AB16 -> 217.14286 | AC17: =(AC18-AC19)*AB15/24*AC16 -> 108.57143 | AD17: =(AD18-AD19)*AD15/24*AD16 -> 130.28571 | AE17: =(AE18-AE19)*AE15/24*AE16 -> 24.285714 | AF17: =(AF18-AF19)*AE15/24*AF16 -> 12.142857 | AG17: =(AG18-AG19)*AG15/24*AG16 -> 14.571429 | AH17: =(AH18-AH19)*AH15/24*AH16 -> 0 | AI17: =(AI18-AI19)*AH15/24*AI16 -> 0 | AJ17: =(AJ18-AJ19)*AJ15/24*AJ16 -> 0 | AK17: =(AK18-AK19)*AK15/24*AK16 -> 0 | AL17: =(AL18-AL19)*AK15/24*AL16 -> 0 | AM17: =(AM18-AM19)*AM15/24*AM16 -> 0 | AN17: =(AN18-AN19)*AN15/24*AN16 -> 0 | AO17: =(AO18-AO19)*AN15/24*AO16 -> 0 | AP17: =(AP18-AP19)*AP15/24*AP16 -> 0 | AQ17: =(AQ18-AQ19)*AQ15/24*AQ16 -> 21.904762 | AR17: =(AR18-AR19)*AQ15/24*AR16 -> 10.952381 | AS17: =(AS18-AS19)*AS15/24*AS16 -> 13.142857 | AT17: =(AT18-AT19)*AT15/24*AT16 -> 212.57143 | AU17: =(AU18-AU19)*AT15/24*AU16 -> 106.28571 | AV17: =(AV18-AV19)*AV15/24*AV16 -> 127.54286 | AW17: =(AW18-AW19)*AW15/24*AW16 -> 277.14286 | AX17: =(AX18-AX19)*AW15/24*AX16 -> 138.57143 | AY17: =(AY18-AY19)*AY15/24*AY16 -> 166.28571 | AZ17: =(AZ18-AZ19)*AZ15/24*AZ16 -> 355.7619 | BA17: =(BA18-BA19)*AZ15/24*BA16 -> 177.88095 | BB17: =(BB18-BB19)*BB15/24*BB16 -> 213.45714 | BC17: D° | BE17: Apríl | BF17: 30 | BG17: 20 | BH17: 9.9 | BI17: =BF17*(BG17-BH17) -> 303 | BJ17: =BI17*0.024 -> 7.272 | BN17: vysokotlaká ortuťová výbojka | BO17: 50 | BP17: 40 – 60 | BQ17: 8.63 | BR17: 0 | BS17: 0.03 | BT17: 12000
L18: Priemerný počet vykurovacích dní: | M18: d | N18: 212 | O18: =U7 -> 0 | Q18: ti : | S18: 20 | T18: =S18-$X$91 -> 20 | U18: =T18 -> 20 | V18: 20 | W18: =V18-$X$91 -> 20 | X18: =W18 -> 20 | Y18: 20 | Z18: =Y18-$X$91 -> 20 | AA18: =Z18 -> 20 | AB18: 20 | AC18: =AB18-$X$91 -> 20 | AD18: =AC18 -> 20 | AE18: 20 | AF18: =AE18-$X$91 -> 20 | AG18: =AF18 -> 20 | AH18: 20 | AI18: =AH18-$X$91 -> 20 | AJ18: =AI18 -> 20 | AK18: 20 | AL18: =AK18-$X$91 -> 20 | AM18: =AL18 -> 20 | AN18: 20 | AO18: =AN18-$X$91 -> 20 | AP18: =AO18 -> 20 | AQ18: 20 | AR18: =AQ18-$X$91 -> 20 | AS18: =AR18 -> 20 | AT18: 20 | AU18: =AT18-$X$91 -> 20 | AV18: =AU18 -> 20 | AW18: 20 | AX18: =AW18-$X$91 -> 20 | AY18: =AX18 -> 20 | AZ18: 20 | BA18: =AZ18-$X$91 -> 20 | BB18: =BA18 -> 20 | BC18: °C | BE18: Október | BF18: 31 | BG18: 20 | BH18: 9.8 | BI18: =BF18*(BG18-BH18) -> 316.2 | BJ18: =BI18*0.024 -> 7.5888 | BN18: halogenidová výbojka | BO18: 75 | BP18: 60 – 130 | BQ18: 39.83 | BR18: 82.98 | BS18: 0.16 | BT18: 12000
L19: Priemerný počet dennostupňov: | M19: D | N19: 3421.5 | O19: =U9 -> 0 | Q19: tem : | S19: -5.7 | T19: =S19 -> -5.7 | U19: =S19 -> -5.7 | V19: -4.1 | W19: =V19 -> -4.1 | X19: =V19 -> -4.1 | Y19: -0.4 | Z19: =Y19 -> -0.4 | AA19: =Y19 -> -0.4 | AB19: 4.8 | AC19: =AB19 -> 4.8 | AD19: =AB19 -> 4.8 | AE19: 9.8 | AF19: =AE19 -> 9.8 | AG19: =AE19 -> 9.8 | AH19: 12.5 | AI19: =AH19 -> 12.5 | AJ19: =AH19 -> 12.5 | AK19: 14 | AL19: =AK19 -> 14 | AM19: =AK19 -> 14 | AN19: 13.4 | AO19: =AN19 -> 13.4 | AP19: =AN19 -> 13.4 | AQ19: 10.8 | AR19: =AQ19 -> 10.8 | AS19: =AQ19 -> 10.8 | AT19: 5.6 | AU19: =AT19 -> 5.6 | AV19: =AT19 -> 5.6 | AW19: 0.6 | AX19: =AW19 -> 0.6 | AY19: =AW19 -> 0.6 | AZ19: -4.1 | BA19: =AZ19 -> -4.1 | BB19: =AZ19 -> -4.1 | BC19: °C | BE19: November | BF19: 30 | BG19: 20 | BH19: 4.3 | BI19: =BF19*(BG19-BH19) -> 471 | BJ19: =BI19*0.024 -> 11.304 | BN19: ortuťová výbojka | BO19: 50 | BP19: 40 – 60 | BQ19: 9.96 | BR19: 0 | BS19: 0.12 | BT19: 24000
Q20: hkr | S20: 2.8 | T20: 2.8 | U20: 2.8 | V20: 2.8 | W20: 2.8 | X20: 2.8 | Y20: 2.8 | Z20: 2.8 | AA20: 2.8 | AB20: 2.8 | AC20: 2.8 | AD20: 2.8 | AE20: 2.8 | AF20: 2.8 | AG20: 2.8 | AH20: 2.8 | AI20: 2.8 | AJ20: 2.8 | AK20: 2.8 | AL20: 2.8 | AM20: 2.8 | AN20: 2.8 | AO20: 2.8 | AP20: 2.8 | AQ20: 2.8 | AR20: 2.8 | AS20: 2.8 | AT20: 2.8 | AU20: 2.8 | AV20: 2.8 | AW20: 2.8 | AX20: 2.8 | AY20: 2.8 | AZ20: 2.8 | BA20: 2.8 | BB20: 2.8 | BC20: m | BE20: December | BF20: 31 | BG20: 20 | BH20: -0.3 | BI20: =BF20*(BG20-BH20) -> 629.3 | BJ20: =BI20*0.024 -> 15.1032 | BN20: induktívna výbojka | BO20: 70 | BP20: 60 – 80 | BQ20: 99.58 | BR20: 132.78 | BS20: 1.17 | BT20: 100000
L21: Súčiniteľ škárovej prievzdušnosti | M21: ivl | BE21: Suma spolu | BF21: =SUM(BF14:BF20) -> 212 | BG21: 20 | BH21: =SUM(BH14:BH20) -> 26.9 | BI21: =SUM(BI14:BI20) -> 3421.5 | BN21: zmesová výbojka – 250 W | BO21: 22 | BP21: 20 – 28 | BQ21: 11.62 | BR21: 0 | BS21: 0.05 | BT21: 16000
L22: kovové okná , škáry medzi rámom a krídlami, netesné | M22: 1.8
L23: drevené okná , škáry medzi rámom a krídlami, netesné | M23: 1.4 | BN23: minimálny inštalovaný príkon nového svietidla | BO23: príkonová rada svietidiel | BY23: Výpočet minimálne inštalovaného príkonu nového svietidla
L24: Drevené, plastové a kovové okná s tesniacim profilom | M24: 1 | BN24: [ W ] | BO24: [ W ] | BY24: [ W ]
L25: iné podľa STN 73 0540-3:2012 | M25: 0.5 | BN25: =IF(AND(AM25>0,AV25>0),AP25/AM25/AV25,0) -> 0 | BO25: =IF($K25="",0,VLOOKUP($K25,$B$28:$R$45,8,FALSE)) -> 0 | BP25: =IF($K25="",0,VLOOKUP($K25,$B$28:$R$45,9,FALSE)) -> 0 | BQ25: =IF($K25="",0,VLOOKUP($K25,$B$28:$R$45,10,FALSE)) -> 0 | BR25: =IF($K25="",0,VLOOKUP($K25,$B$28:$R$45,11,FALSE)) -> 0 | BS25: =IF($K25="",0,VLOOKUP($K25,$B$28:$R$45,12,FALSE)) -> 0 | BT25: =IF($K25="",0,VLOOKUP($K25,$B$28:$R$45,13,FALSE)) -> 0 | BU25: =IF($K25="",0,VLOOKUP($K25,$B$28:$R$45,14,FALSE)) -> 0 | BV25: =IF($K25="",0,VLOOKUP($K25,$B$28:$R$45,15,FALSE)) -> 0 | BW25: =IF($K25="",0,VLOOKUP($K25,$B$28:$R$45,16,FALSE)) -> 0 | BX25: =IF($K25="",0,VLOOKUP($K25,$B$28:$R$45,17,FALSE)) -> 0 | BY25: =IF(BO25>=BN25,BO25,IF(BP25>=BN25,BP25,IF(BQ25>=BN25,BQ25,IF(BR25>=BN25,BR25,IF(BS25>=BN25,BS25,IF(BT25>=BN25,BT25,IF(BU25>=BN25,BU25,IF(BV25>=BN25,BV25,0)))))))) -> 0 | BZ25: =IF(BY25>0,BY25,IF(BW25>BN25,BW25,IF(BX25>BN25,BX25,BN25))) -> 0
BN26: =IF(AND(AM26>0,AV26>0),AP26/AM26/AV26,0) -> 0 | BO26: =IF($K26="",0,VLOOKUP($K26,$B$28:$R$45,8,FALSE)) -> 0 | BP26: =IF($K26="",0,VLOOKUP($K26,$B$28:$R$45,9,FALSE)) -> 0 | BQ26: =IF($K26="",0,VLOOKUP($K26,$B$28:$R$45,10,FALSE)) -> 0 | BR26: =IF($K26="",0,VLOOKUP($K26,$B$28:$R$45,11,FALSE)) -> 0 | BS26: =IF($K26="",0,VLOOKUP($K26,$B$28:$R$45,12,FALSE)) -> 0 | BT26: =IF($K26="",0,VLOOKUP($K26,$B$28:$R$45,13,FALSE)) -> 0 | BU26: =IF($K26="",0,VLOOKUP($K26,$B$28:$R$45,14,FALSE)) -> 0 | BV26: =IF($K26="",0,VLOOKUP($K26,$B$28:$R$45,15,FALSE)) -> 0 | BW26: =IF($K26="",0,VLOOKUP($K26,$B$28:$R$45,16,FALSE)) -> 0 | BX26: =IF($K26="",0,VLOOKUP($K26,$B$28:$R$45,17,FALSE)) -> 0 | BY26: =IF(BO26>=BN26,BO26,IF(BP26>=BN26,BP26,IF(BQ26>=BN26,BQ26,IF(BR26>=BN26,BR26,IF(BS26>=BN26,BS26,IF(BT26>=BN26,BT26,IF(BU26>=BN26,BU26,IF(BV26>=BN26,BV26,0)))))))) -> 0 | BZ26: =IF(BY26>0,BY26,IF(BW26>BN26,BW26,IF(BX26>BN26,BX26,BN26))) -> 0
L27: Tepelná strata cez konštrukciu | M27: bx | BN27: =IF(AND(AM27>0,AV27>0),AP27/AM27/AV27,0) -> 0 | BO27: =IF($K27="",0,VLOOKUP($K27,$B$28:$R$45,8,FALSE)) -> 0 | BP27: =IF($K27="",0,VLOOKUP($K27,$B$28:$R$45,9,FALSE)) -> 0 | BQ27: =IF($K27="",0,VLOOKUP($K27,$B$28:$R$45,10,FALSE)) -> 0 | BR27: =IF($K27="",0,VLOOKUP($K27,$B$28:$R$45,11,FALSE)) -> 0 | BS27: =IF($K27="",0,VLOOKUP($K27,$B$28:$R$45,12,FALSE)) -> 0 | BT27: =IF($K27="",0,VLOOKUP($K27,$B$28:$R$45,13,FALSE)) -> 0 | BU27: =IF($K27="",0,VLOOKUP($K27,$B$28:$R$45,14,FALSE)) -> 0 | BV27: =IF($K27="",0,VLOOKUP($K27,$B$28:$R$45,15,FALSE)) -> 0 | BW27: =IF($K27="",0,VLOOKUP($K27,$B$28:$R$45,16,FALSE)) -> 0 | BX27: =IF($K27="",0,VLOOKUP($K27,$B$28:$R$45,17,FALSE)) -> 0 | BY27: =IF(BO27>=BN27,BO27,IF(BP27>=BN27,BP27,IF(BQ27>=BN27,BQ27,IF(BR27>=BN27,BR27,IF(BS27>=BN27,BS27,IF(BT27>=BN27,BT27,IF(BU27>=BN27,BU27,IF(BV27>=BN27,BV27,0)))))))) -> 0 | BZ27: =IF(BY27>0,BY27,IF(BW27>BN27,BW27,IF(BX27>BN27,BX27,BN27))) -> 0
L28: vonkajšia stena, okno, dvere | M28: 1 | BN28: =IF(AND(AM28>0,AV28>0),AP28/AM28/AV28,0) -> 0 | BO28: =IF($K28="",0,VLOOKUP($K28,$B$28:$R$45,8,FALSE)) -> 0 | BP28: =IF($K28="",0,VLOOKUP($K28,$B$28:$R$45,9,FALSE)) -> 0 | BQ28: =IF($K28="",0,VLOOKUP($K28,$B$28:$R$45,10,FALSE)) -> 0 | BR28: =IF($K28="",0,VLOOKUP($K28,$B$28:$R$45,11,FALSE)) -> 0 | BS28: =IF($K28="",0,VLOOKUP($K28,$B$28:$R$45,12,FALSE)) -> 0 | BT28: =IF($K28="",0,VLOOKUP($K28,$B$28:$R$45,13,FALSE)) -> 0 | BU28: =IF($K28="",0,VLOOKUP($K28,$B$28:$R$45,14,FALSE)) -> 0 | BV28: =IF($K28="",0,VLOOKUP($K28,$B$28:$R$45,15,FALSE)) -> 0 | BW28: =IF($K28="",0,VLOOKUP($K28,$B$28:$R$45,16,FALSE)) -> 0 | BX28: =IF($K28="",0,VLOOKUP($K28,$B$28:$R$45,17,FALSE)) -> 0 | BY28: =IF(BO28>=BN28,BO28,IF(BP28>=BN28,BP28,IF(BQ28>=BN28,BQ28,IF(BR28>=BN28,BR28,IF(BS28>=BN28,BS28,IF(BT28>=BN28,BT28,IF(BU28>=BN28,BU28,IF(BV28>=BN28,BV28,0)))))))) -> 0 | BZ28: =IF(BY28>0,BY28,IF(BW28>BN28,BW28,IF(BX28>BN28,BX28,BN28))) -> 0
L29: strecha(plochá, šikmá) na teplovýmennom obale budovy | M29: 1 | BN29: =IF(AND(AM29>0,AV29>0),AP29/AM29/AV29,0) -> 0 | BO29: =IF($K29="",0,VLOOKUP($K29,$B$28:$R$45,8,FALSE)) -> 0 | BP29: =IF($K29="",0,VLOOKUP($K29,$B$28:$R$45,9,FALSE)) -> 0 | BQ29: =IF($K29="",0,VLOOKUP($K29,$B$28:$R$45,10,FALSE)) -> 0 | BR29: =IF($K29="",0,VLOOKUP($K29,$B$28:$R$45,11,FALSE)) -> 0 | BS29: =IF($K29="",0,VLOOKUP($K29,$B$28:$R$45,12,FALSE)) -> 0 | BT29: =IF($K29="",0,VLOOKUP($K29,$B$28:$R$45,13,FALSE)) -> 0 | BU29: =IF($K29="",0,VLOOKUP($K29,$B$28:$R$45,14,FALSE)) -> 0 | BV29: =IF($K29="",0,VLOOKUP($K29,$B$28:$R$45,15,FALSE)) -> 0 | BW29: =IF($K29="",0,VLOOKUP($K29,$B$28:$R$45,16,FALSE)) -> 0 | BX29: =IF($K29="",0,VLOOKUP($K29,$B$28:$R$45,17,FALSE)) -> 0 | BY29: =IF(BO29>=BN29,BO29,IF(BP29>=BN29,BP29,IF(BQ29>=BN29,BQ29,IF(BR29>=BN29,BR29,IF(BS29>=BN29,BS29,IF(BT29>=BN29,BT29,IF(BU29>=BN29,BU29,IF(BV29>=BN29,BV29,0)))))))) -> 0 | BZ29: =IF(BY29>0,BY29,IF(BW29>BN29,BW29,IF(BX29>BN29,BX29,BN29))) -> 0
L30: podlaha na teréne | M30: 1 | BN30: =IF(AND(AM30>0,AV30>0),AP30/AM30/AV30,0) -> 0 | BO30: =IF($K30="",0,VLOOKUP($K30,$B$28:$R$45,8,FALSE)) -> 0 | BP30: =IF($K30="",0,VLOOKUP($K30,$B$28:$R$45,9,FALSE)) -> 0 | BQ30: =IF($K30="",0,VLOOKUP($K30,$B$28:$R$45,10,FALSE)) -> 0 | BR30: =IF($K30="",0,VLOOKUP($K30,$B$28:$R$45,11,FALSE)) -> 0 | BS30: =IF($K30="",0,VLOOKUP($K30,$B$28:$R$45,12,FALSE)) -> 0 | BT30: =IF($K30="",0,VLOOKUP($K30,$B$28:$R$45,13,FALSE)) -> 0 | BU30: =IF($K30="",0,VLOOKUP($K30,$B$28:$R$45,14,FALSE)) -> 0 | BV30: =IF($K30="",0,VLOOKUP($K30,$B$28:$R$45,15,FALSE)) -> 0 | BW30: =IF($K30="",0,VLOOKUP($K30,$B$28:$R$45,16,FALSE)) -> 0 | BX30: =IF($K30="",0,VLOOKUP($K30,$B$28:$R$45,17,FALSE)) -> 0 | BY30: =IF(BO30>=BN30,BO30,IF(BP30>=BN30,BP30,IF(BQ30>=BN30,BQ30,IF(BR30>=BN30,BR30,IF(BS30>=BN30,BS30,IF(BT30>=BN30,BT30,IF(BU30>=BN30,BU30,IF(BV30>=BN30,BV30,0)))))))) -> 0 | BZ30: =IF(BY30>0,BY30,IF(BW30>BN30,BW30,IF(BX30>BN30,BX30,BN30))) -> 0
L31: podlaha povaly | M31: 0.8 | BN31: =IF(AND(AM31>0,AV31>0),AP31/AM31/AV31,0) -> 0 | BO31: =IF($K31="",0,VLOOKUP($K31,$B$28:$R$45,8,FALSE)) -> 0 | BP31: =IF($K31="",0,VLOOKUP($K31,$B$28:$R$45,9,FALSE)) -> 0 | BQ31: =IF($K31="",0,VLOOKUP($K31,$B$28:$R$45,10,FALSE)) -> 0 | BR31: =IF($K31="",0,VLOOKUP($K31,$B$28:$R$45,11,FALSE)) -> 0 | BS31: =IF($K31="",0,VLOOKUP($K31,$B$28:$R$45,12,FALSE)) -> 0 | BT31: =IF($K31="",0,VLOOKUP($K31,$B$28:$R$45,13,FALSE)) -> 0 | BU31: =IF($K31="",0,VLOOKUP($K31,$B$28:$R$45,14,FALSE)) -> 0 | BV31: =IF($K31="",0,VLOOKUP($K31,$B$28:$R$45,15,FALSE)) -> 0 | BW31: =IF($K31="",0,VLOOKUP($K31,$B$28:$R$45,16,FALSE)) -> 0 | BX31: =IF($K31="",0,VLOOKUP($K31,$B$28:$R$45,17,FALSE)) -> 0 | BY31: =IF(BO31>=BN31,BO31,IF(BP31>=BN31,BP31,IF(BQ31>=BN31,BQ31,IF(BR31>=BN31,BR31,IF(BS31>=BN31,BS31,IF(BT31>=BN31,BT31,IF(BU31>=BN31,BU31,IF(BV31>=BN31,BV31,0)))))))) -> 0 | BZ31: =IF(BY31>0,BY31,IF(BW31>BN31,BW31,IF(BX31>BN31,BX31,BN31))) -> 0
L32: stena medzi vyk a nevyk priestorom a podstrešným priestorom | M32: 0.8 | BN32: =IF(AND(AM32>0,AV32>0),AP32/AM32/AV32,0) -> 0 | BO32: =IF($K32="",0,VLOOKUP($K32,$B$28:$R$45,8,FALSE)) -> 0 | BP32: =IF($K32="",0,VLOOKUP($K32,$B$28:$R$45,9,FALSE)) -> 0 | BQ32: =IF($K32="",0,VLOOKUP($K32,$B$28:$R$45,10,FALSE)) -> 0 | BR32: =IF($K32="",0,VLOOKUP($K32,$B$28:$R$45,11,FALSE)) -> 0 | BS32: =IF($K32="",0,VLOOKUP($K32,$B$28:$R$45,12,FALSE)) -> 0 | BT32: =IF($K32="",0,VLOOKUP($K32,$B$28:$R$45,13,FALSE)) -> 0 | BU32: =IF($K32="",0,VLOOKUP($K32,$B$28:$R$45,14,FALSE)) -> 0 | BV32: =IF($K32="",0,VLOOKUP($K32,$B$28:$R$45,15,FALSE)) -> 0 | BW32: =IF($K32="",0,VLOOKUP($K32,$B$28:$R$45,16,FALSE)) -> 0 | BX32: =IF($K32="",0,VLOOKUP($K32,$B$28:$R$45,17,FALSE)) -> 0 | BY32: =IF(BO32>=BN32,BO32,IF(BP32>=BN32,BP32,IF(BQ32>=BN32,BQ32,IF(BR32>=BN32,BR32,IF(BS32>=BN32,BS32,IF(BT32>=BN32,BT32,IF(BU32>=BN32,BU32,IF(BV32>=BN32,BV32,0)))))))) -> 0 | BZ32: =IF(BY32>0,BY32,IF(BW32>BN32,BW32,IF(BX32>BN32,BX32,BN32))) -> 0
L33: stena alebo strop nevykurovaného suterénu | M33: 0.5 | BN33: =IF(AND(AM33>0,AV33>0),AP33/AM33/AV33,0) -> 0 | BO33: =IF($K33="",0,VLOOKUP($K33,$B$28:$R$45,8,FALSE)) -> 0 | BP33: =IF($K33="",0,VLOOKUP($K33,$B$28:$R$45,9,FALSE)) -> 0 | BQ33: =IF($K33="",0,VLOOKUP($K33,$B$28:$R$45,10,FALSE)) -> 0 | BR33: =IF($K33="",0,VLOOKUP($K33,$B$28:$R$45,11,FALSE)) -> 0 | BS33: =IF($K33="",0,VLOOKUP($K33,$B$28:$R$45,12,FALSE)) -> 0 | BT33: =IF($K33="",0,VLOOKUP($K33,$B$28:$R$45,13,FALSE)) -> 0 | BU33: =IF($K33="",0,VLOOKUP($K33,$B$28:$R$45,14,FALSE)) -> 0 | BV33: =IF($K33="",0,VLOOKUP($K33,$B$28:$R$45,15,FALSE)) -> 0 | BW33: =IF($K33="",0,VLOOKUP($K33,$B$28:$R$45,16,FALSE)) -> 0 | BX33: =IF($K33="",0,VLOOKUP($K33,$B$28:$R$45,17,FALSE)) -> 0 | BY33: =IF(BO33>=BN33,BO33,IF(BP33>=BN33,BP33,IF(BQ33>=BN33,BQ33,IF(BR33>=BN33,BR33,IF(BS33>=BN33,BS33,IF(BT33>=BN33,BT33,IF(BU33>=BN33,BU33,IF(BV33>=BN33,BV33,0)))))))) -> 0 | BZ33: =IF(BY33>0,BY33,IF(BW33>BN33,BW33,IF(BX33>BN33,BX33,BN33))) -> 0
L34: stena alebo strop temperovaného priestoru | M34: 0.35
L35: otvorená dilatácia | M35: 0.35
L36: uzavretá izolovaná dilatácia do šírkou do 0,05m | M36: 0.1
L37: stena a otvorená konštrukcia do nevyk priestoru, ktorý má zasklenie - jednoduché | M37: 0.7
L38: stena a otvorená konštrukcia do nevyk priestoru, ktorý má zasklenie - dvojité | M38: 0.6
L39: stena a otvorená konštrukcia do nevyk priestoru, ktorý má zasklenie - dvojsklo | M39: 0.5
L40: strop nad otvoreným prejazdom | M40: 1

Sheet Dennostupne
G1: 2001 | I1: 2002 | K1: 2003 | M1: 2004 | O1: 2005 | Q1: 2006 | S1: 2007 | U1: 2008 | W1: 2009 | Y1: 2010 | AA1: 2011 | AC1: 2012 | AE1: 2013 | AG1: 2014 | AI1: 2015 | AK1: 2016 | AM1: 2017 | AO1: 2018 | AQ1: 2019
A2: KOD_OKRES | B2: NAZOV_OKRES | C2: SKRATKA_OKRES | D2: NAZOV_KRAJ | E2: Vonkajšia výpočtová teplota | F2: Veterná oblasť | G2: Počet vykur.dní | H2: Priem. vonk. teplota | I2: Počet vykur.dní | J2: Priem. vonk. teplota | K2: Počet vykur.dní | L2: Priem. vonk. teplota | M2: Počet vykur.dní | N2: Priem. vonk. teplota | O2: Počet vykur.dní | P2: Priem. vonk. teplota | Q2: Počet vykur.dní | R2: Priem. vonk. teplota | S2: Počet vykur.dní | T2: Priem. vonk. teplota | U2: Počet vykur.dní | V2: Priem. vonk. teplota | W2: Počet vykur.dní | X2: Priem. vonk. teplota | Y2: Počet vykur.dní | Z2: Priem. vonk. teplota | AA2: Počet vykur.dní | AB2: Priem. vonk. teplota | AC2: Počet vykur.dní | AD2: Priem. vonk. teplota | AE2: Počet vykur.dní | AF2: Priem. vonk. teplota | AG2: Počet vykur.dní | AH2: Priem. vonk. teplota | AI2: Počet vykur.dní | AJ2: Priem. vonk. teplota | AK2: Počet vykur.dní | AL2: Priem. vonk. teplota | AM2: Počet vykur.dní | AN2: Priem. vonk. teplota | AO2: Počet vykur.dní | AP2: Priem. vonk. teplota | AQ2: Počet vykur.dní | AR2: Priem. vonk. teplota
A3: 301 | B3: Bánovce nad Bebravou | C3: BN | D3: Trenčín | E3: -12 | F3: od 2 do 5 | G3: 210 | H3: 3.5 | I3: 211 | J3: 4.4 | K3: 209 | L3: 3.5 | M3: 211 | N3: 4.1 | O3: 209 | P3: 3.5 | Q3: 208 | R3: 4 | S3: 202 | T3: 5.4 | U3: 210 | V3: 6.1 | W3: 174 | X3: 3.3 | Y3: 215 | Z3: 4.2 | AA3: 197 | AB3: 4.3 | AC3: 205 | AD3: 4.7 | AE3: 202 | AF3: 4.6 | AG3: 186 | AH3: 6.7 | AI3: 197 | AJ3: 5.7 | AK3: 215 | AL3: 5.5 | AM3: 233 | AN3: 3.9 | AO3: 187 | AP3: 4.8
A4: 601 | B4: Banská Bystrica | C4: BB | D4: Banská Bystrica | E4: -15 | F4: < 2,0 | G4: 226 | H4: 3.1 | I4: 230 | J4: 3.8 | K4: 221 | L4: 2.5 | M4: 239 | N4: 3.8 | O4: 228 | P4: 2.8 | Q4: 223 | R4: 3.1 | S4: 245 | T4: 5.5 | U4: 242 | V4: 5.4 | W4: 182 | X4: 2 | Y4: 239 | Z4: 3.8 | AA4: 203 | AB4: 2.8 | AC4: 217 | AD4: 3.3 | AE4: 214 | AF4: 3.5 | AG4: 239 | AH4: 6.7 | AI4: 208 | AJ4: 4.9 | AK4: 232 | AL4: 4.4 | AM4: 237 | AN4: 3.9 | AO4: 201 | AP4: 3.5
A5: 602 | B5: Banská Štiavnica | C5: BS | D5: Banská Bystrica | E5: -16 | F5: < 2,0 | G5: 240 | H5: 3.3 | I5: 234 | J5: 3.7 | K5: 224 | L5: 2.4 | M5: 251 | N5: 4.2 | O5: 242 | P5: 3.5 | Q5: 237 | R5: 3.5 | S5: 246 | T5: 4.9 | U5: 244 | V5: 4.8 | W5: 212 | X5: 3 | Y5: 246 | Z5: 3.4 | AA5: 215 | AB5: 2.7 | AC5: 220 | AD5: 3.1 | AE5: 216 | AF5: 3 | AG5: 231 | AH5: 5.8 | AI5: 214 | AJ5: 4.6 | AK5: 230 | AL5: 3.8 | AM5: 239 | AN5: 4.1 | AO5: 189 | AP5: 2.7
A6: 701 | B6: Bardejov | C6: BJ | D6: Prešov | E6: -15 | F6: od 2 do 5 | G6: 225 | H6: 2.9 | I6: 223 | J6: 3.3 | K6: 228 | L6: 2.4 | M6: 243 | N6: 3.6 | O6: 229 | P6: 2.5 | Q6: 225 | R6: 2.7 | S6: 250 | T6: 4.8 | U6: 242 | V6: 4.8 | W6: 233 | X6: 3.9 | Y6: 234 | Z6: 2.6 | AA6: 222 | AB6: 2.3 | AC6: 218 | AD6: 2.4 | AE6: 223 | AF6: 3.2 | AG6: 237 | AH6: 5.8 | AI6: 219 | AJ6: 4.4 | AK6: 244 | AL6: 4.2 | AM6: 231 | AN6: 3.4 | AO6: 196 | AP6: 2.6
A7: 101 | B7: Bratislava I | C7: BA1 | D7: Bratislava | E7: -11 | F7: od 2 do 5 | G7: 205 | H7: 3.9 | I7: 207 | J7: 5.1 | K7: 200 | L7: 3.4 | M7: 205 | N7: 4.1 | O7: 211 | P7: 4.1 | Q7: 197 | R7: 4.3 | S7: 192 | T7: 5.2 | U7: 214 | V7: 6.3 | W7: 175 | X7: 3.3 | Y7: 215 | Z7: 4 | AA7: 190 | AB7: 4.6 | AC7: 201 | AD7: 4.7 | AE7: 202 | AF7: 4.7 | AG7: 182 | AH7: 6.2 | AI7: 183 | AJ7: 5.6 | AK7: 206 | AL7: 5.3 | AM7: 207 | AN7: 5.5 | AO7: 181 | AP7: 4.7
A8: 102 | B8: Bratislava II | C8: BA2 | D8: Bratislava | E8: -11 | F8: od 2 do 5 | G8: 205 | H8: 3.9 | I8: 207 | J8: 5.1 | K8: 200 | L8: 3.4 | M8: 205 | N8: 4.1 | O8: 211 | P8: 4.1 | Q8: 197 | R8: 4.3 | S8: 192 | T8: 5.2 | U8: 214 | V8: 6.3 | W8: 175 | X8: 3.3 | Y8: 215 | Z8: 4 | AA8: 190 | AB8: 4.6 | AC8: 201 | AD8: 4.7 | AE8: 202 | AF8: 4.7 | AG8: 182 | AH8: 6.2 | AI8: 183 | AJ8: 5.6 | AK8: 205 | AL8: 5.3 | AM8: 207 | AN8: 5.5 | AO8: 181 | AP8: 4.7
A9: 103 | B9: Bratislava III | C9: BA3 | D9: Bratislava | E9: -11 | F9: od 2 do 5 | G9: 205 | H9: 3.9 | I9: 207 | J9: 5.1 | K9: 200 | L9: 3.4 | M9: 205 | N9: 4.1 | O9: 211 | P9: 4.1 | Q9: 192 | R9: 3.5 | S9: 192 | T9: 5.2 | U9: 215 | V9: 6 | W9: 175 | X9: 2.7 | Y9: 214 | Z9: 3.7 | AA9: 197 | AB9: 4.3 | AC9: 193 | AD9: 3.7 | AE9: 206 | AF9: 4.2 | AG9: 194 | AH9: 6.7 | AI9: 187 | AJ9: 5.5 | AK9: 209 | AL9: 5 | AM9: 207 | AN9: 5.5 | AO9: 182 | AP9: 4.1
A10: 104 | B10: Bratislava IV | C10: BA4 | D10: Bratislava | E10: -11 | F10: od 2 do 5 | G10: 205 | H10: 3.9 | I10: 207 | J10: 5.1 | K10: 200 | L10: 3.4 | M10: 205 | N10: 4.1 | O10: 211 | P10: 4.1 | Q10: 192 | R10: 3.5 | S10: 192 | T10: 5.2 | U10: 215 | V10: 6 | W10: 175 | X10: 3.3 | Y10: 215 | Z10: 4 | AA10: 190 | AB10: 4.6 | AC10: 201 | AD10: 4.7 | AE10: 202 | AF10: 4.6 | AG10: 182 | AH10: 6.2 | AI10: 192 | AJ10: 6.3 | AK10: 209 | AL10: 5.3 | AM10: 203 | AN10: 5.1 | AO10: 182 | AP10: 4.5
A11: 105 | B11: Bratislava V | C11: BA5 | D11: Bratislava | E11: -11 | F11: od 2 do 5 | G11: 205 | H11: 3.9 | I11: 207 | J11: 5.1 | K11: 200 | L11: 3.4 | M11: 205 | N11: 4.1 | O11: 211 | P11: 4.1 | Q11: 192 | R11: 3.5 | S11: 192 | T11: 5.2 | U11: 214 | V11: 6.3 | W11: 175 | X11: 3.3 | Y11: 215 | Z11: 4 | AA11: 190 | AB11: 4.6 | AC11: 201 | AD11: 4.7 | AE11: 202 | AF11: 4.7 | AG11: 182 | AH11: 6.2 | AI11: 192 | AJ11: 6.3 | AK11: 209 | AL11: 5 | AM11: 203 | AN11: 5.1 | AO11: 181 | AP11: 4.7
A12: 603 | B12: Brezno | C12: BR | D12: Banská Bystrica | E12: -16 | F12: < 2,0 | G12: 237 | H12: 2.5 | I12: 236 | J12: 2.7 | K12: 233 | L12: 1.4 | M12: 252 | N12: 3.1 | O12: 247 | P12: 2 | Q12: 248 | R12: 2.7 | S12: 252 | T12: 4.4 | U12: 246 | V12: 4.4 | W12: 235 | X12: 3.5 | Y12: 250 | Z12: 3.2 | AA12: 231 | AB12: 2.7 | AC12: 222 | AD12: 1.9 | AE12: 228 | AF12: 3.1 | AG12: 238 | AH12: 5.9 | AI12: 221 | AJ12: 5.1 | AK12: 239 | AL12: 3.8 | AM12: 237 | AN12: 2.7 | AO12: 209 | AP12: 2.5
A13: 501 | B13: Bytča | C13: BY | D13: Žilina | E13: -15 | F13: < 2,0 | G13: 236 | H13: 3.3 | I13: 229 | J13: 3.4 | K13: 227 | L13: 2.6 | M13: 241 | N13: 3.7 | O13: 247 | P13: 3.2 | Q13: 227 | R13: 2.8 | S13: 258 | T13: 5.7 | U13: 242 | V13: 5.4 | W13: 212 | X13: 3.5 | Y13: 242 | Z13: 3.4 | AA13: 217 | AB13: 2.8 | AC13: 219 | AD13: 2.9 | AE13: 221 | AF13: 3.5 | AG13: 215 | AH13: 5.1 | AI13: 216 | AJ13: 4.7 | AK13: 229 | AL13: 4.3 | AM13: 233 | AN13: 4.1 | AO13: 202 | AP13: 3.6
A14: 502 | B14: Čadca | C14: CA | D14: Žilina | E14: -15 | F14: < 2,0 | G14: 243 | H14: 2.9 | I14: 240 | J14: 3.1 | K14: 239 | L14: 2.1 | M14: 264 | N14: 3.7 | O14: 261 | P14: 3 | Q14: 249 | R14: 3 | S14: 265 | T14: 4.9 | U14: 253 | V14: 5 | W14: 235 | X14: 3.3 | Y14: 257 | Z14: 2.8 | AA14: 247 | AB14: 3.6 | AC14: 242 | AD14: 2.7 | AE14: 250 | AF14: 3.4 | AG14: 239 | AH14: 5.3 | AI14: 242 | AJ14: 4.4 | AK14: 248 | AL14: 3.7 | AM14: 254 | AN14: 3.8 | AO14: 202 | AP14: 2.7
... A26: 802 | B26: Košice I | C26: KE1 | D26: Košice | E26: -13 | F26: od 2 do 5 | G26: 213 | H26: 3.5 | I26: 219 | J26: 3.9 | K26: 214 | L26: 2.5 | M26: 227 | N26: 3.9 | O26: 214 | P26: 3.2 | Q26: 209 | R26: 3.3 | S26: 204 | T26: 4.7 | U26: 216 | V26: 5.2 | W26: 181 | X26: 2.9 | Y26: 230 | Z26: 4 | AA26: 202 | AB26: 3 | AC26: 209 | AD26: 3.5 | AE26: 198 | AF26: 3.7 | AG26: 200 | AH26: 6.3 | AI26: 201 | AJ26: 4.7 | AK26: 208 | AL26: 3.9 | AM26: 225 | AN26: 4.4 | AO26: 188 | AP26: 3.5
A27: 803 | B27: Košice II | C27: KE2 | D27: Košice | E27: -13 | F27: od 2 do 5 | G27: 213 | H27: 3.5 | I27: 219 | J27: 3.9 | K27: 214 | L27: 2.5 | M27: 227 | N27: 3.9 | O27: 214 | P27: 3.2 | Q27: 209 | R27: 3.3 | S27: 204 | T27: 4.7 | U27: 216 | V27: 5.2 | W27: 181 | X27: 2.9 | Y27: 230 | Z27: 4 | AA27: 202 | AB27: 3 | AC27: 209 | AD27: 3.5 | AE27: 198 | AF27: 3.7 | AG27: 200 | AH27: 6.3 | AI27: 201 | AJ27: 4.7 | AK27: 208 | AL27: 3.9 | AM27: 225 | AN27: 4.4 | AO27: 188 | AP27: 3.5 | AQ27: 219 | AR27: 5.6
A28: 804 | B28: Košice III | C28: KE3 | D28: Košice | E28: -13 | F28: od 2 do 5 | G28: 213 | H28: 3.5 | I28: 219 | J28: 3.9 | K28: 214 | L28: 2.5 | M28: 227 | N28: 3.9 | O28: 214 | P28: 3.2 | Q28: 209 | R28: 3.3 | S28: 204 | T28: 4.7 | U28: 216 | V28: 5.2 | W28: 181 | X28: 2.9 | Y28: 230 | Z28: 4 | AA28: 202 | AB28: 3 | AC28: 209 | AD28: 3.5 | AE28: 198 | AF28: 3.7 | AG28: 200 | AH28: 6.3 | AI28: 201 | AJ28: 4.7 | AK28: 208 | AL28: 3.9 | AM28: 225 | AN28: 4.4 | AO28: 188 | AP28: 3.5
A29: 805 | B29: Košice IV | C29: KE4 | D29: Košice | E29: -13 | F29: od 2 do 5 | G29: 213 | H29: 3.5 | I29: 219 | J29: 3.9 | K29: 214 | L29: 2.5 | M29: 227 | N29: 3.9 | O29: 214 | P29: 3.2 | Q29: 209 | R29: 3.3 | S29: 204 | T29: 4.7 | U29: 216 | V29: 5.2 | W29: 181 | X29: 2.9 | Y29: 230 | Z29: 4 | AA29: 202 | AB29: 3 | AC29: 209 | AD29: 3.5 | AE29: 198 | AF29: 3.7 | AG29: 203 | AH29: 5.9 | AI29: 201 | AJ29: 4.7 | AK29: 208 | AL29: 3.9 | AM29: 225 | AN29: 4.4 | AO29: 188 | AP29: 3.5
A30: 605 | B30: Krupina | C30: KA | D30: Banská Bystrica | E30: -13 | F30: < 2,0 | G30: 223 | H30: 3.2 | I30: 225 | J30: 4.1 | K30: 217 | L30: 2.6 | M30: 224 | N30: 3.6 | O30: 222 | P30: 3.1 | Q30: 228 | R30: 3.8 | S30: 235 | T30: 5.2 | U30: 238 | V30: 5.4 | W30: 189 | X30: 2.7 | Y30: 239 | Z30: 3.9 | AA30: 202 | AB30: 2.9 | AC30: 212 | AD30: 3.4 | AE30: 213 | AF30: 4 | AG30: 211 | AH30: 6.2 | AI30: 207 | AJ30: 4.6 | AK30: 217 | AL30: 4.8 | AM30: 218 | AN30: 3.8 | AO30: 188 | AP30: 3.3
A31: 504 | B31: Kysucké Nové Mesto | C31: KM | D31: Žilina | E31: -13 | F31: < 2,0 | G31: 245 | H31: 3.5 | I31: 229 | J31: 3.5 | K31: 228 | L31: 2.6 | M31: 246 | N31: 3.9 | O31: 247 | P31: 3.2 | Q31: 223 | R31: 2.7 | S31: 239 | T31: 5 | U31: 245 | V31: 5.5 | W31: 227 | X31: 4 | Y31: 253 | Z31: 3 | AA31: 228 | AB31: 3.6 | AC31: 217 | AD31: 2.9 | AE31: 241 | AF31: 3.7 | AG31: 220 | AH31: 5.3 | AI31: 214 | AJ31: 5 | AK31: 238 | AL31: 4.6 | AM31: 233 | AN31: 4.1 | AO31: 200 | AP31: 3.2
A32: 402 | B32: Levice | C32: LV | D32: Nitra | E32: -11 | F32: < 2,0 | G32: 207 | H32: 3.2 | I32: 216 | J32: 4.7 | K32: 205 | L32: 2.9 | M32: 215 | N32: 3.9 | O32: 215 | P32: 3.9 | Q32: 207 | R32: 3.9 | S32: 207 | T32: 5.4 | U32: 208 | V32: 5.4 | W32: 174 | X32: 2.6 | Y32: 216 | Z32: 3.7 | AA32: 202 | AB32: 3.8 | AC32: 212 | AD32: 4.5 | AE32: 206 | AF32: 4.3 | AG32: 196 | AH32: 6.4 | AI32: 195 | AJ32: 5.2 | AK32: 214 | AL32: 4.7 | AM32: 217 | AN32: 4.7 | AO32: 182 | AP32: 4
A33: 704 | B33: Levoča | C33: LE | D33: Prešov | E33: -16 | F33: < 2,0 | G33: 237 | H33: 2.9 | I33: 234 | J33: 3 | K33: 234 | L33: 1.7 | M33: 251 | N33: 3.4 | O33: 255 | P33: 2.7 | Q33: 254 | R33: 3 | S33: 245 | T33: 4.5 | U33: 243 | V33: 4.6 | W33: 232 | X33: 3.6 | Y33: 245 | Z33: 2.9 | AA33: 223 | AB33: 2.4 | AC33: 216 | AD33: 2.1 | AE33: 232 | AF33: 3 | AG33: 240 | AH33: 5.2 | AI33: 227 | AJ33: 3.8 | AK33: 237 | AL33: 3.6 | AM33: 239 | AN33: 3 | AO33: 210 | AP33: 2.2
A34: 505 | B34: Liptovský Mikuláš | C34: LM | D34: Žilina | E34: -16 | F34: < 2,0 | G34: 250 | H34: 2.7 | I34: 237 | J34: 2.6 | K34: 238 | L34: 1.7 | M34: 265 | N34: 3.2 | O34: 247 | P34: 1.9 | Q34: 249 | R34: 2.3 | S34: 264 | T34: 4.5 | U34: 246 | V34: 4.4 | W34: 234 | X34: 3.1 | Y34: 248 | Z34: 2.9 | AA34: 201 | AB34: 2.4 | AC34: 225 | AD34: 1.9 | AE34: 237 | AF34: 3.3 | AG34: 234 | AH34: 5.6 | AI34: 228 | AJ34: 4.6 | AK34: 244 | AL34: 3.8 | AM34: 254 | AN34: 3.5 | AO34: 209 | AP34: 2.8
A35: 606 | B35: Lučenec | C35: LC | D35: Banská Bystrica | E35: -13 | F35: < 2,0 | G35: 215 | H35: 3 | I35: 220 | J35: 3.9 | K35: 214 | L35: 2.1 | M35: 228 | N35: 4 | O35: 211 | P35: 2.7 | Q35: 219 | R35: 3.7 | S35: 226 | T35: 5.4 | U35: 237 | V35: 5.8 | W35: 180 | X35: 2.7 | Y35: 209 | Z35: 3.1 | AA35: 203 | AB35: 3.2 | AC35: 211 | AD35: 3.6 | AE35: 208 | AF35: 4 | AG35: 208 | AH35: 6.3 | AI35: 200 | AJ35: 5.3 | AK35: 210 | AL35: 4.1 | AM35: 225 | AN35: 4.1 | AO35: 191 | AP35: 3.5
A36: 106 | B36: Malacky | C36: MA | D36: Bratislava | E36: -11 | F36: od 2 do 5 | G36: 208 | H36: 4.2 | I36: 208 | J36: 5.3 | K36: 209 | L36: 3.7 | M36: 217 | N36: 4.4 | O36: 208 | P36: 3.5 | Q36: 192 | R36: 3.5 | S36: 196 | T36: 5.1 | U36: 228 | V36: 6.1 | W36: 176 | X36: 2.9 | Y36: 218 | Z36: 3.7 | AA36: 207 | AB36: 4.2 | AC36: 213 | AD36: 4.5 | AE36: 203 | AF36: 4.1 | AG36: 193 | AH36: 6.1 | AI36: 197 | AJ36: 5.9 | AK36: 211 | AL36: 4.9 | AM36: 223 | AN36: 5 | AO36: 182 | AP36: 4.2
A37: 506 | B37: Martin | C37: MT | D37: Žilina | E37: -15 | F37: < 2,0 | G37: 244 | H37: 3.6 | I37: 228 | J37: 3.4 | K37: 226 | L37: 2.3 | M37: 259 | N37: 3.7 | O37: 264 | P37: 3.2 | Q37: 244 | R37: 2.8 | S37: 258 | T37: 5.1 | U37: 253 | V37: 5.2 | W37: 227 | X37: 3.3 | Y37: 256 | Z37: 3 | AA37: 222 | AB37: 2.9 | AC37: 218 | AD37: 2.7 | AE37: 222 | AF37: 3.6 | AG37: 221 | AH37: 6.1 | AI37: 214 | AJ37: 5.2 | AK37: 243 | AL37: 4.8 | AM37: 257 | AN37: 4 | AO37: 202 | AP37: 3.5 | AQ37: 241 | AR37: 5.2
A38: 705 | B38: Medzilaborce | C38: ML | D38: Prešov | E38: -15 | F38: od 2 do 5 | G38: 245 | H38: 3.1 | I38: 228 | J38: 2.8 | K38: 237 | L38: 2 | M38: 252 | N38: 3.4 | O38: 238 | P38: 2.5 | Q38: 240 | R38: 3 | S38: 257 | T38: 4.7 | U38: 242 | V38: 4.4 | W38: 242 | X38: 4.2 | Y38: 239 | Z38: 2.8 | AA38: 235 | AB38: 2.9 | AC38: 230 | AD38: 2.8 | AE38: 228 | AF38: 3.3 | AG38: 234 | AH38: 5.5 | AI38: 224 | AJ38: 4.2 | AK38: 240 | AL38: 3.8 | AM38: 235 | AN38: 3.4 | AO38: 201 | AP38: 2.7
A39: 807 | B39: Michalovce | C39: MI | D39: Košice | E39: -13 | F39: od 2 do 5 | G39: 205 | H39: 3.5 | I39: 213 | J39: 4.2 | K39: 209 | L39: 2.6 | M39: 218 | N39: 4 | O39: 210 | P39: 3.1 | Q39: 202 | R39: 3.3 | S39: 207 | T39: 5.2 | U39: 216 | V39: 5.4 | W39: 181 | X39: 3.3 | Y39: 209 | Z39: 3.5 | AA39: 197 | AB39: 3 | AC39: 207 | AD39: 3.6 | AE39: 213 | AF39: 4.6 | AG39: 199 | AH39: 6.2 | AI39: 189 | AJ39: 4.7 | AK39: 207 | AL39: 4.5 | AM39: 219 | AN39: 4.3 | AO39: 196 | AP39: 4.4
A40: 303 | B40: Myjava | C40: MY | D40: Trenčín | E40: -13 | F40: od 2 do 5 | G40: 236 | H40: 3.5 | I40: 226 | J40: 3.9 | K40: 226 | L40: 2.7 | M40: 234 | N40: 3.5 | O40: 226 | P40: 3.1 | Q40: 224 | R40: 3.6 | S40: 245 | T40: 5.6 | U40: 233 | V40: 5.3 | W40: 177 | X40: 2 | Y40: 214 | Z40: 2.9 | AA40: 203 | AB40: 3.5 | AC40: 213 | AD40: 3.5 | AE40: 223 | AF40: 4.4 | AG40: 231 | AH40: 4.8 | AI40: 216 | AJ40: 4.7 | AK40: 223 | AL40: 5.1 | AM40: 230 | AN40: 3.9 | AO40: 188 | AP40: 3.4
A41: 507 | B41: Námestovo | C41: NO | D41: Žilina | E41: -18 | F41: < 2,0 | G41: 271 | H41: 2.5 | I41: 256 | J41: 2.6 | K41: 250 | L41: 1.4 | M41: 285 | N41: 3.5 | O41: 263 | P41: 2 | Q41: 266 | R41: 2.9 | S41: 265 | T41: 3.8 | U41: 254 | V41: 3.9 | W41: 250 | X41: 2.8 | Y41: 279 | Z41: 2.6 | AA41: 246 | AB41: 2.5 | AC41: 247 | AD41: 2 | AE41: 261 | AF41: 3.1 | AG41: 258 | AH41: 4.9 | AI41: 245 | AJ41: 3.7 | AK41: 246 | AL41: 2.9 | AM41: 268 | AN41: 3.4 | AO41: 218 | AP41: 2.3
A42: 403 | B42: Nitra | C42: NR | D42: Nitra | E42: -11 | F42: od 2 do 5 | G42: 213 | H42: 3.8 | I42: 209 | J42: 4.7 | K42: 204 | L42: 3.2 | M42: 209 | N42: 4.1 | O42: 209 | P42: 3.8 | Q42: 198 | R42: 3.9 | S42: 208 | T42: 5.6 | U42: 216 | V42: 6 | W42: 175 | X42: 3.1 | Y42: 216 | Z42: 3.9 | AA42: 203 | AB42: 4.1 | AC42: 208 | AD42: 4.7 | AE42: 201 | AF42: 4.5 | AG42: 189 | AH42: 6.5 | AI42: 189 | AJ42: 5.1 | AK42: 214 | AL42: 5.3 | AM42: 217 | AN42: 4.7 | AO42: 189 | AP42: 4.8
A43: 304 | B43: Nové Mesto nad Váhom | C43: NM | D43: Trenčín | E43: -11 | F43: od 2 do 5 | G43: 214 | H43: 3.9 | I43: 225 | J43: 4.4 | K43: 218 | L43: 3.2 | M43: 223 | N43: 3.9 | O43: 228 | P43: 3.9 | Q43: 207 | R43: 4.5 | S43: 226 | T43: 6.6 | U43: 233 | V43: 5.3 | W43: 176 | X43: 2.6 | Y43: 216 | Z43: 3.7 | AA43: 202 | AB43: 3.8 | AC43: 213 | AD43: 4.5 | AE43: 216 | AF43: 4.3 | AG43: 231 | AH43: 4.8 | AI43: 216 | AJ43: 4.7 | AK43: 193 | AL43: 4 | AM43: 230 | AN43: 3.9 | AO43: 187 | AP43: 4.3
A44: 404 | B44: Nové Zámky | C44: NZ | D44: Nitra | E44: -11 | F44: od 2 do 5 | G44: 200 | H44: 3.8 | I44: 209 | J44: 5.4 | K44: 199 | L44: 3.3 | M44: 202 | N44: 4.2 | O44: 203 | P44: 3.6 | Q44: 187 | R44: 3.6 | S44: 207 | T44: 5.2 | U44: 200 | V44: 5.7 | W44: 183 | X44: 3.9 | Y44: 211 | Z44: 4.1 | AA44: 199 | AB44: 4.5 | AC44: 202 | AD44: 4.8 | AE44: 197 | AF44: 4.8 | AG44: 193 | AH44: 6.5 | AI44: 188 | AJ44: 5 | AK44: 216 | AL44: 5.1 | AM44: 210 | AN44: 5.3 | AO44: 180 | AP44: 4.9
A45: 305 | B45: Partizánske | C45: PE | D45: Trenčín | E45: -13 | F45: od 2 do 5 | G45: 210 | H45: 3.5 | I45: 211 | J45: 4.4 | K45: 209 | L45: 3.5 | M45: 211 | N45: 4.1 | O45: 209 | P45: 3.5 | Q45: 208 | R45: 4 | S45: 202 | T45: 5.4 | U45: 210 | V45: 6.1 | W45: 174 | X45: 3.3 | Y45: 215 | Z45: 4.2 | AA45: 197 | AB45: 4.3 | AC45: 205 | AD45: 4.7 | AE45: 202 | AF45: 4.6 | AG45: 186 | AH45: 6.7 | AI45: 197 | AJ45: 5.7 | AK45: 224 | AL45: 7.8 | AM45: 233 | AN45: 3.9 | AO45: 187 | AP45: 4.8
A46: 107 | B46: Pezinok | C46: PK | D46: Bratislava | E46: -11 | F46: od 2 do 5 | G46: 203 | H46: 4 | I46: 206 | J46: 5 | K46: 200 | L46: 3.6 | M46: 205 | N46: 4.4 | O46: 213 | P46: 4.3 | Q46: 226 | R46: 3.8 | S46: 200 | T46: 5.6 | U46: 205 | V46: 6 | W46: 175 | X46: 3.1 | Y46: 217 | Z46: 4 | AA46: 201 | AB46: 4.3 | AC46: 207 | AD46: 4.8 | AE46: 203 | AF46: 4.7 | AG46: 189 | AH46: 6.5 | AI46: 214 | AJ46: 4.8 | AK46: 231 | AL46: 4 | AM46: 208 | AN46: 5.2 | AO46: 188 | AP46: 4.8
A47: 204 | B47: Piešťany | C47: PN | D47: Trnava | E47: -11 | F47: od 2 do 5 | G47: 215 | H47: 3.8 | I47: 218 | J47: 4.7 | K47: 209 | L47: 3.2 | M47: 208 | N47: 3.8 | O47: 210 | P47: 3.6 | Q47: 212 | R47: 4.1 | S47: 213 | T47: 5.4 | U47: 225 | V47: 6 | W47: 177 | X47: 2.9 | Y47: 217 | Z47: 3.7 | AA47: 202 | AB47: 3.8 | AC47: 213 | AD47: 4.5 | AE47: 214 | AF47: 4.5 | AG47: 196 | AH47: 6.5 | AI47: 196 | AJ47: 5.2 | AK47: 220 | AL47: 5 | AM47: 225 | AN47: 4.7 | AO47: 182 | AP47: 4.2
A48: 607 | B48: Poltár | C48: PT | D48: Banská Bystrica | E48: -13 | F48: < 2,0 | G48: 219 | H48: 3.2 | I48: 225 | J48: 4.1 | K48: 216 | L48: 2.4 | M48: 232 | N48: 3.9 | O48: 218 | P48: 3 | Q48: 182 | R48: 2.8 | S48: 226 | T48: 4.9 | U48: 233 | V48: 5.3 | W48: 188 | X48: 2.7 | Y48: 219 | Z48: 3.2 | AA48: 204 | AB48: 2.8 | AC48: 212 | AD48: 3.3 | AE48: 213 | AF48: 3.6 | AG48: 226 | AH48: 6.5 | AI48: 215 | AJ48: 4.5 | AK48: 245 | AL48: 2.3 | AM48: 225 | AN48: 4.1 | AO48: 194 | AP48: 3.5
A49: 706 | B49: Poprad | C49: PP | D49: Prešov | E49: -16 | F49: od 2 do 5 | G49: 259 | H49: 2.5 | I49: 248 | J49: 2.6 | K49: 249 | L49: 1.6 | M49: 273 | N49: 3 | O49: 262 | P49: 2.1 | Q49: 280 | R49: 3.1 | S49: 261 | T49: 4 | U49: 256 | V49: 4 | W49: 230 | X49: 2.1 | Y49: 262 | Z49: 2.4 | AA49: 231 | AB49: 1.9 | AC49: 230 | AD49: 1.5 | AE49: 247 | AF49: 2.7 | AG49: 260 | AH49: 5.1 | AI49: 244 | AJ49: 4.3 | AK49: 245 | AL49: 3 | AM49: 251 | AN49: 2.9 | AO49: 218 | AP49: 2.2
... A57: 508 | B57: Ružomberok | C57: RK | D57: Žilina | E57: -16 | F57: < 2,0 | G57: 250 | H57: 2.7 | I57: 234 | J57: 3.6 | K57: 228 | L57: 2.4 | M57: 241 | N57: 3.8 | O57: 230 | P57: 2.7 | Q57: 237 | R57: 2.8 | S57: 246 | T57: 5.2 | U57: 241 | V57: 5.2 | W57: 230 | X57: 3.4 | Y57: 247 | Z57: 3.2 | AA57: 205 | AB57: 3 | AC57: 219 | AD57: 2.6 | AE57: 238 | AF57: 3.3 | AG57: 246 | AH57: 5.8 | AI57: 235 | AJ57: 4.4 | AK57: 244 | AL57: 4 | AM57: 257 | AN57: 4 | AO57: 202 | AP57: 2.6
A58: 708 | B58: Sabinov | C58: SB | D58: Prešov | E58: -15 | F58: < 2,0 | G58: 229 | H58: 2.9 | I58: 227 | J58: 3.3 | K58: 229 | L58: 2.3 | M58: 239 | N58: 3.3 | O58: 242 | P58: 3.3 | Q58: 225 | R58: 2.9 | S58: 245 | T58: 4.9 | U58: 246 | V58: 5.1 | W58: 220 | X58: 3.5 | Y58: 236 | Z58: 3 | AA58: 206 | AB58: 2.2 | AC58: 217 | AD58: 2.4 | AE58: 225 | AF58: 3.3 | AG58: 239 | AH58: 5.9 | AI58: 220 | AJ58: 4.6 | AK58: 244 | AL58: 4.1 | AM58: 251 | AN58: 3 | AO58: 196 | AP58: 2.9 | AQ58: 233 | AR58: 5.3
...

Sheet Hárok7
B2: Adresa hodnoteného objektu
B3: Okres: | F3: Dunajská Streda
B4: Mesto / obec: | F4: Bratislava II
B5: Ulica, číslo:
B6: Kategória budovy | F6: budova určená na šport
B7: Rok spracovania energetického auditu: | F7: 2020
B9: Geometrické parametre objektu
B10: Celková zastavaná plocha (m2) | F10: A | G10: 4021
B11: Obvod zastavanej plochy (m) | F11: P | G11: 352
B12: Obostavaný vykurovaný objem (m3) | F12: Vb | G12: 26762.25
B13: Celková podlahová plocha (m2) | F13: Ab | G13: 5301.5
B14: Ochladzovaná obalová konštrukcia (m2) | F14: ∑Ai | G14: ='[2]9_tepelna strata'!C133 -> 10756.1
B15: Faktor tvaru budovy (m-1) | F15: ∑Ai/Vb | G15: =G14/G12 -> 0.40191315
B16: Počet nadzemných podlaží | G16: 2
B17: Priemerná konštrukčná výška podlažia (m) | F17: hk,pr | G17: 6.5
B19: Dennostupne
B20: Kalendárny rok | D20: =F7-10 -> 2010 | E20: =F7-9 -> 2011 | F20: =F7-8 -> 2012 | G20: =F7-7 -> 2013 | H20: =F7-6 -> 2014 | I20: =F7-5 -> 2015 | J20: =F7-4 -> 2016 | K20: =F7-3 -> 2017 | L20: =F7-2 -> 2018 | M20: =F7-1 -> 2019 | N20: Priemer
B21: Počet vykurovacích dní | D21: =VLOOKUP($F$3,#REF!,D25,FALSE) -> #REF! | E21: =VLOOKUP($F$3,#REF!,E25,FALSE) -> #REF! | F21: =VLOOKUP($F$3,#REF!,F25,FALSE) -> #REF! | G21: =VLOOKUP($F$3,#REF!,G25,FALSE) -> #REF! | H21: =VLOOKUP($F$3,#REF!,H25,FALSE) -> #REF! | I21: =VLOOKUP($F$3,#REF!,I25,FALSE) -> #REF! | J21: =VLOOKUP($F$3,#REF!,J25,FALSE) -> #REF! | K21: =VLOOKUP($F$3,#REF!,K25,FALSE) -> #REF! | ... M21: =VLOOKUP($F$3,#REF!,M25,FALSE) -> #REF! | N21: =SUM(D21:M21)/COUNT(D21:M21) -> #REF!
B22: Priemerná vonk. teplota (oC) | D22: =VLOOKUP($F$3,#REF!,D25+1,FALSE) -> #REF! | E22: =VLOOKUP($F$3,#REF!,E25+1,FALSE) -> #REF! | F22: =VLOOKUP($F$3,#REF!,F25+1,FALSE) -> #REF! | G22: =VLOOKUP($F$3,#REF!,G25+1,FALSE) -> #REF! | H22: =VLOOKUP($F$3,#REF!,H25+1,FALSE) -> #REF! | I22: =VLOOKUP($F$3,#REF!,I25+1,FALSE) -> #REF! | J22: =VLOOKUP($F$3,#REF!,J25+1,FALSE) -> #REF! | K22: =VLOOKUP($F$3,#REF!,K25+1,FALSE) -> #REF! | ... M22: =VLOOKUP($F$3,#REF!,M25+1,FALSE) -> #REF! | N22: =SUM(D22:M22)/COUNT(D22:M22) -> #REF!
B23: Počet dennostupňov | D23: =IF(ISNUMBER(D22),($H$30-D22)*D21,"-") -> - | E23: =IF(ISNUMBER(E22),($H$30-E22)*E21,"-") -> - | F23: =IF(ISNUMBER(F22),($H$30-F22)*F21,"-") -> - | G23: =IF(ISNUMBER(G22),($H$30-G22)*G21,"-") -> - | H23: =IF(ISNUMBER(H22),($H$30-H22)*H21,"-") -> - | I23: =IF(ISNUMBER(I22),($H$30-I22)*I21,"-") -> - | J23: =IF(ISNUMBER(J22),($H$30-J22)*J21,"-") -> - | K23: =IF(ISNUMBER(K22),($H$30-K22)*K21,"-") -> - | ... M23: =IF(ISNUMBER(M22),($H$30-M22)*M21,"-") -> - | N23: =($H$30-N22)*N21 -> #REF!
B24: priemer | D24: =$N23 -> #REF! | E24: =$N23 -> #REF! | F24: =$N23 -> #REF! | G24: =$N23 -> #REF! | H24: =$N23 -> #REF! | I24: =$N23 -> #REF! | J24: =$N23 -> #REF! | K24: =$N23 -> #REF! | ... M24: =$N23 -> #REF!
B25: číslo stĺpca | D25: =MATCH(D20,'[2]cis_dennost.'!$B$1:$AL$1) -> 24 | E25: =MATCH(E20,'[2]cis_dennost.'!$B$1:$AL$1) -> 26 | F25: =MATCH(F20,'[2]cis_dennost.'!$B$1:$AL$1) -> 28 | G25: =MATCH(G20,'[2]cis_dennost.'!$B$1:$AL$1) -> 30 | H25: =MATCH(H20,'[2]cis_dennost.'!$B$1:$AL$1) -> 32 | I25: =MATCH(I20,'[2]cis_dennost.'!$B$1:$AL$1) -> 34 | J25: =MATCH(J20,'[2]cis_dennost.'!$B$1:$AL$1) -> 36 | K25: =MATCH(K20,'[2]cis_dennost.'!$B$1:$AL$1) -> 36 | ... M25: =MATCH(M20,'[2]cis_dennost.'!$B$1:$AL$1) -> 36
B26: Klimatické údaje
G27: Normalizované hodnotenie | H27: Upravené hodnotenie
B28: Vonkajšia výpočtová teplota (oC): | F28: qe | G28: -15 | H28: =VLOOKUP(F3,'[2]cis_dennost.'!B3:E81,4,FALSE) -> -11
B29: Veterná oblasť, rýchlosť vetra (ms-1) | F29: v | G29: - | H29: =VLOOKUP(F3,'[2]cis_dennost.'!B3:F81,5,FALSE) -> od 2 do 5
B30: Vnútorná výpočtová teplota (oC): | F30: qi | G30: =IF(E47=G166,VLOOKUP(F6,J206:P213,6,FALSE),VLOOKUP(F6,J206:P213,4,FALSE)) -> #N/A | H30: =J59 -> 0
B31: Priemerná vonkajšia teplota vykurovacieho obdobia (oC): | F31: qae | G31: 3.86 | H31: =N22 -> #REF!
B32: Priemerný počet vykurovacích dní: | F32: d | G32: 212 | H32: =N21 -> #REF!
B33: Priemerný počet dennostupňov: | F33: D | G33: =VLOOKUP(F6,J206:P213,7,FALSE) -> #N/A | H33: =N23 -> #REF!

Sheet Konstrukcie
A1: SO1 | B1: Obvodová stena ŠD | E1: 465.1 | I1: STR1 | J1: Plochá strecha ŠD | M1: 825.5 | Q1: PDL1 | R1: Podlaha na teréne ŽS | U1: 825.5
A2: Odpor pri prestupe tepla na vnútornej strane k-cie | D2: Rsi = | E2: 0.13 | I2: Odpor pri prestupe tepla na vnútornej strane k-cie | L2: Rsi = | M2: 0.1 | Q2: Odpor pri prestupe tepla na vnútornej strane k-cie | T2: Rsi = | U2: 0.17 | V2: posudenie na R
A3: Názov vrstvy konštrukcie | C3: dj [m] | D3: λj [W/(m.K)] | E3: Rj [m2.K/W] | I3: Názov vrstvy konštrukcie | K3: dj [m] | L3: λj [W/(m.K)] | M3: Rj [m2.K/W] | Q3: Názov vrstvy konštrukcie | S3: dj [m] | T3: λj [W/(m.K)] | U3: Rj [m2.K/W]
A4: Vápennocementová omietka | C4: 0.0015 | D4: 0.9 | E4: =C4/D4 -> 0.0016666667 | I4: TI minerálna vlna | K4: 0.12 | L4: 0.05 | M4: =K4/L4 -> 2.4
A5: Pórobetónové tvárnice | C5: 0.3 | D5: 0.35 | E5: =C5/D5 -> 0.85714286 | I5: Spiroll | K5: 0.25 | L5: 1.2 | M5: =K5/L5 -> 0.20833333 | Q5: cementový poter | S5: 0.033 | T5: 1.16 | U5: =S5/T5 -> 0.028448276
A6: TI minerálna vlna | C6: 0.08 | D6: 0.04 | E6: =C6/D6 -> 2 | I6: TI čadič | K6: 0.12 | L6: 0.08 | M6: =K6/L6 -> 1.5 | Q6: betón hutný | S6: 0.055 | T6: 1.02 | U6: =S6/T6 -> 0.053921569
I7: vzduchová medzera | K7: 0.18 | L7: 1.3 | M7: =K7/L7 -> 0.13846154 | Q7: TI | S7: 0.06 | T7: 0.05 | U7: =S7/T7 -> 1.2
I8: HI | K8: 0.002 | L8: 0.16 | M8: =K8/L8 -> 0.0125
I9: pórobetónový panel | K9: 0.25 | L9: 0.35 | M9: =K9/L9 -> 0.71428571 | Q9: HI PVC fólia | S9: 0.002 | T9: 0.21 | U9: =S9/T9 -> 0.0095238095
A10: Celková hrúbka konštrukcie | C10: =SUM(C4:C7) -> 0.3815 | D10: ∑Rj = | E10: =SUM(E4:E6) -> 2.8588095
A11: Odpor pri prestupe tepla na vonkajšej strane k-cie | D11: Rse = | E11: 0.04 | I11: Celková hrúbka konštrukcie | K11: =SUM(K4:K9) -> 0.922 | L11: ∑Rj = | M11: =SUM(M4:M9) -> 4.9735806
A12: Odpor konštrukcie pri prechode tepla | D12: R0 = | E12: =E2+E10+E11 -> 3.0288095 | I12: Odpor pri prestupe tepla na vonkajšej strane k-cie | L12: Rse = | M12: 0.04 | Q12: Celková hrúbka konštrukcie | S12: =SUM(S4:S10) -> 0.15 | T12: ∑Rj = | U12: =SUM(U4:U10) -> 1.2918937
A13: Súčiniteľ prechodu tepla | D13: U = | E13: =1/(E2+E10+E11) -> 0.33016272 | I13: Odpor konštrukcie pri prechode tepla | L13: R0 = | M13: =M2+M11+M12 -> 5.1135806 | Q13: Odpor pri prestupe tepla na vonkajšej strane k-cie | T13: Rse = | U13: 0.04 | Z13: 0.439
I14: Súčiniteľ prechodu tepla | L14: U = | M14: =1/(M2+M11+M12) -> 0.19555769 | Q14: Odpor konštrukcie pri prechode tepla | T14: R0 = | U14: =U2+U12+U13 -> 1.5018937
A15: SO2 | B15: Obvodová stena ŠD2 | E15: 1217.2 | Q15: Súčiniteľ prechodu tepla | T15: U = | U15: 0.26
A16: Odpor pri prestupe tepla na vnútornej strane k-cie | D16: Rsi = | E16: 0.13 | I16: STR2 | J16: Strecha Jedáleň | M16: 1104.7
A17: Názov vrstvy konštrukcie | C17: dj [m] | D17: λj [W/(m.K)] | E17: Rj [m2.K/W] | I17: Odpor pri prestupe tepla na vnútornej strane k-cie | L17: Rsi = | M17: 0.1 | Q17: PDL2 | R17: Podlaha na teréne Jedáleň | U17: 1104.7
A18: Vápennocementová omietka | C18: 0.012 | D18: 0.9 | E18: =C18/D18 -> 0.013333333 | I18: Názov vrstvy konštrukcie | K18: dj [m] | L18: λj [W/(m.K)] | M18: Rj [m2.K/W] | Q18: Odpor pri prestupe tepla na vnútornej strane k-cie | T18: Rsi = | U18: 0.17
A19: ŽB panel | C19: 0.15 | D19: 1.58 | E19: =C19/D19 -> 0.094936709 | I19: TI minerálna vlna | K19: 0.12 | L19: 0.05 | M19: =K19/L19 -> 2.4 | Q19: Názov vrstvy konštrukcie | S19: dj [m] | T19: λj [W/(m.K)] | U19: Rj [m2.K/W]
A20: Pórobetónové tvárnice | C20: 0.3 | D20: 0.35 | E20: =C20/D20 -> 0.85714286 | I20: Spiroll | K20: 0.25 | L20: 1.13 | M20: =K20/L20 -> 0.22123894 | Q20: cementový poter + povrchová vrstva | S20: 0.025 | T20: 1.16 | U20: =S20/T20 -> 0.021551724
A21: TI minerálna vlna | C21: 0.08 | D21: 0.04 | E21: =C21/D21 -> 2 | I21: TI čadič | K21: 0.12 | L21: 0.08 | M21: =K21/L21 -> 1.5 | Q21: betónová mazanina | S21: 0.063 | T21: 1.02 | U21: =S21/T21 -> 0.061764706
I22: vzudhcová medzera | K22: 0.175 | L22: 1.1 | M22: =K22/L22 -> 0.15909091 | Q22: TI | S22: 0.06 | T22: 0.05 | U22: =S22/T22 -> 1.2
A23: Celková hrúbka konštrukcie | C23: =SUM(C18:C21) -> 0.542 | D23: ∑Rj = | E23: =SUM(E18:E21) -> 2.9654129 | I23: drevený panel KSDD | K23: 0.128 | L23: 0.22 | M23: =K23/L23 -> 0.58181818 | Q23: HI | S23: 0.002 | T23: 0.21 | U23: =S23/T23 -> 0.0095238095
A24: Odpor pri prestupe tepla na vonkajšej strane k-cie | D24: Rse = | E24: 0.04 | I24: HI | K24: 0.002 | L24: 0.16 | M24: =K24/L24 -> 0.0125
A25: Odpor konštrukcie pri prechode tepla | D25: R0 = | E25: =E16+E23+E24 -> 3.1354129 | Q25: Celková hrúbka konštrukcie | S25: =SUM(S20:S23) -> 0.15 | T25: ∑Rj = | U25: =SUM(U20:U23) -> 1.2928402
A26: Súčiniteľ prechodu tepla | D26: U = | E26: =1/(E16+E23+E24) -> 0.31893726 | I26: Celková hrúbka konštrukcie | K26: =SUM(K19:K21) -> 0.49 | L26: ∑Rj = | M26: =SUM(M19:M24) -> 4.874648 | Q26: Odpor pri prestupe tepla na vonkajšej strane k-cie | T26: Rse = | U26: 0.04
I27: Odpor pri prestupe tepla na vonkajšej strane k-cie | L27: Rse = | M27: 0.04 | Q27: Odpor konštrukcie pri prechode tepla | T27: R0 = | U27: =U18+U25+U26 -> 1.5028402
A28: SO3 | B28: Obvodová stena - Nezateplená časť | E28: 307.8 | I28: Odpor konštrukcie pri prechode tepla | L28: R0 = | M28: =M17+M26+M27 -> 5.014648 | Q28: Súčiniteľ prechodu tepla | T28: U = | U28: 0.22
A29: Odpor pri prestupe tepla na vnútornej strane k-cie | D29: Rsi = | E29: 0.13 | I29: Súčiniteľ prechodu tepla | L29: U = | M29: =1/(M17+M26+M27) -> 0.19941579
A30: Názov vrstvy konštrukcie | C30: dj [m] | D30: λj [W/(m.K)] | E30: Rj [m2.K/W]
A31: Vápennocementová omietka | C31: 0.012 | D31: 0.9 | E31: =C31/D31 -> 0.013333333
A32: betón ŽB | C32: 0.15 | D32: 1.7 | E32: =C32/D32 -> 0.088235294
A33: pórobetón | C33: 0.3 | D33: 0.3 | E33: =C33/D33 -> 1
A38: Celková hrúbka konštrukcie | C38: =SUM(C31:C36) -> 0.462 | D38: ∑Rj = | E38: =SUM(E31:E36) -> 1.1015686
A39: Odpor pri prestupe tepla na vonkajšej strane k-cie | D39: Rse = | E39: 0.04
A40: Odpor konštrukcie pri prechode tepla | D40: R0 = | E40: =E29+E38+E39 -> 1.2715686
A41: Súčiniteľ prechodu tepla | D41: U = | E41: =1/(E29+E38+E39) -> 0.78643022
A43: SO4 | B43: Obvodová stena Jedáleň | E43: 333
A44: Odpor pri prestupe tepla na vnútornej strane k-cie | D44: Rsi = | E44: 0.13
A45: Názov vrstvy konštrukcie | C45: dj [m] | D45: λj [W/(m.K)] | E45: Rj [m2.K/W]
...

Sheet Konstrukcie nové
A1: SO1 | B1: Obvodová stena ŠD | E1: 465.1 | I1: STR1 | J1: Plochá strecha ŠD | M1: 825.5 | Q1: PDL1 | R1: Podlaha na teréne ŽS | U1: 825.5
A2: Odpor pri prestupe tepla na vnútornej strane k-cie | D2: Rsi = | E2: 0.13 | I2: Odpor pri prestupe tepla na vnútornej strane k-cie | L2: Rsi = | M2: 0.1 | Q2: Odpor pri prestupe tepla na vnútornej strane k-cie | T2: Rsi = | U2: 0.17 | V2: posudenie na R
A3: Názov vrstvy konštrukcie | C3: dj [m] | D3: λj [W/(m.K)] | E3: Rj [m2.K/W] | I3: Názov vrstvy konštrukcie | K3: dj [m] | L3: λj [W/(m.K)] | M3: Rj [m2.K/W] | Q3: Názov vrstvy konštrukcie | S3: dj [m] | T3: λj [W/(m.K)] | U3: Rj [m2.K/W]
A4: Vápennocementová omietka | C4: 0.0015 | D4: 0.9 | E4: =C4/D4 -> 0.0016666667 | I4: TI minerálna vlna | K4: 0.23 | L4: 0.05 | M4: =K4/L4 -> 4.6
A5: Pórobetónové tvárnice | C5: 0.3 | D5: 0.35 | E5: =C5/D5 -> 0.85714286 | I5: Spiroll | K5: 0.25 | L5: 1.2 | M5: =K5/L5 -> 0.20833333 | Q5: cementový poter | S5: 0.033 | T5: 1.16 | U5: =S5/T5 -> 0.028448276
A6: TI minerálna vlna | C6: 0.15 | D6: 0.04 | E6: =C6/D6 -> 3.75 | I6: TI čadič | K6: 0.12 | L6: 0.08 | M6: =K6/L6 -> 1.5 | Q6: betón hutný | S6: 0.055 | T6: 1.02 | U6: =S6/T6 -> 0.053921569
I7: vzduchová medzera | K7: 0.18 | L7: 1.3 | M7: =K7/L7 -> 0.13846154 | Q7: TI | S7: 0.06 | T7: 0.05 | U7: =S7/T7 -> 1.2
I8: HI | K8: 0.002 | L8: 0.16 | M8: =K8/L8 -> 0.0125
I9: pórobetónový panel | K9: 0.25 | L9: 0.35 | M9: =K9/L9 -> 0.71428571 | Q9: HI PVC fólia | S9: 0.002 | T9: 0.21 | U9: =S9/T9 -> 0.0095238095
A10: Celková hrúbka konštrukcie | C10: =SUM(C4:C7) -> 0.4515 | D10: ∑Rj = | E10: =SUM(E4:E6) -> 4.6088095
A11: Odpor pri prestupe tepla na vonkajšej strane k-cie | D11: Rse = | E11: 0.04 | I11: Celková hrúbka konštrukcie | K11: =SUM(K4:K9) -> 1.032 | L11: ∑Rj = | M11: =SUM(M4:M9) -> 7.1735806
A12: Odpor konštrukcie pri prechode tepla | D12: R0 = | E12: =E2+E10+E11 -> 4.7788095 | I12: Odpor pri prestupe tepla na vonkajšej strane k-cie | L12: Rse = | M12: 0.04 | Q12: Celková hrúbka konštrukcie | S12: =SUM(S4:S10) -> 0.15 | T12: ∑Rj = | U12: =SUM(U4:U10) -> 1.2918937
A13: Súčiniteľ prechodu tepla | D13: U = | E13: =1/(E2+E10+E11) -> 0.20925714 | I13: Odpor konštrukcie pri prechode tepla | L13: R0 = | M13: =M2+M11+M12 -> 7.3135806 | Q13: Odpor pri prestupe tepla na vonkajšej strane k-cie | T13: Rse = | U13: 0.04 | Z13: 0.439
I14: Súčiniteľ prechodu tepla | L14: U = | M14: =1/(M2+M11+M12) -> 0.13673193 | Q14: Odpor konštrukcie pri prechode tepla | T14: R0 = | U14: =U2+U12+U13 -> 1.5018937
A15: SO2 | B15: Obvodová stena ŠD2 | E15: 1217.2 | Q15: Súčiniteľ prechodu tepla | T15: U = | U15: 0.26
A16: Odpor pri prestupe tepla na vnútornej strane k-cie | D16: Rsi = | E16: 0.13 | I16: STR2 | J16: Strecha Jedáleň | M16: 1104.7
A17: Názov vrstvy konštrukcie | C17: dj [m] | D17: λj [W/(m.K)] | E17: Rj [m2.K/W] | I17: Odpor pri prestupe tepla na vnútornej strane k-cie | L17: Rsi = | M17: 0.1 | Q17: PDL2 | R17: Podlaha na teréne Jedáleň | U17: 1104.7
A18: Vápennocementová omietka | C18: 0.012 | D18: 0.9 | E18: =C18/D18 -> 0.013333333 | I18: Názov vrstvy konštrukcie | K18: dj [m] | L18: λj [W/(m.K)] | M18: Rj [m2.K/W] | Q18: Odpor pri prestupe tepla na vnútornej strane k-cie | T18: Rsi = | U18: 0.17
A19: ŽB panel | C19: 0.15 | D19: 1.58 | E19: =C19/D19 -> 0.094936709 | I19: TI minerálna vlna | K19: 0.22 | L19: 0.05 | M19: =K19/L19 -> 4.4 | Q19: Názov vrstvy konštrukcie | S19: dj [m] | T19: λj [W/(m.K)] | U19: Rj [m2.K/W]
A20: Pórobetónové tvárnice | C20: 0.3 | D20: 0.35 | E20: =C20/D20 -> 0.85714286 | I20: Spiroll | K20: 0.25 | L20: 1.13 | M20: =K20/L20 -> 0.22123894 | Q20: cementový poter + povrchová vrstva | S20: 0.025 | T20: 1.16 | U20: =S20/T20 -> 0.021551724
A21: TI minerálna vlna | C21: 0.14 | D21: 0.04 | E21: =C21/D21 -> 3.5 | I21: TI čadič | K21: 0.12 | L21: 0.08 | M21: =K21/L21 -> 1.5 | Q21: betónová mazanina | S21: 0.063 | T21: 1.02 | U21: =S21/T21 -> 0.061764706
I22: vzudhcová medzera | K22: 0.175 | L22: 1.1 | M22: =K22/L22 -> 0.15909091 | Q22: TI | S22: 0.06 | T22: 0.05 | U22: =S22/T22 -> 1.2
A23: Celková hrúbka konštrukcie | C23: =SUM(C18:C21) -> 0.602 | D23: ∑Rj = | E23: =SUM(E18:E21) -> 4.4654129 | I23: drevený panel KSDD | K23: 0.128 | L23: 0.22 | M23: =K23/L23 -> 0.58181818 | Q23: HI | S23: 0.002 | T23: 0.21 | U23: =S23/T23 -> 0.0095238095
A24: Odpor pri prestupe tepla na vonkajšej strane k-cie | D24: Rse = | E24: 0.04 | I24: HI | K24: 0.002 | L24: 0.16 | M24: =K24/L24 -> 0.0125
A25: Odpor konštrukcie pri prechode tepla | D25: R0 = | E25: =E16+E23+E24 -> 4.6354129 | Q25: Celková hrúbka konštrukcie | S25: =SUM(S20:S23) -> 0.15 | T25: ∑Rj = | U25: =SUM(U20:U23) -> 1.2928402
A26: Súčiniteľ prechodu tepla | D26: U = | E26: =1/(E16+E23+E24) -> 0.21573051 | I26: Celková hrúbka konštrukcie | K26: =SUM(K19:K21) -> 0.59 | L26: ∑Rj = | M26: =SUM(M19:M24) -> 6.874648 | Q26: Odpor pri prestupe tepla na vonkajšej strane k-cie | T26: Rse = | U26: 0.04
I27: Odpor pri prestupe tepla na vonkajšej strane k-cie | L27: Rse = | M27: 0.04 | Q27: Odpor konštrukcie pri prechode tepla | T27: R0 = | U27: =U18+U25+U26 -> 1.5028402
A28: SO3 | B28: Obvodová stena - Nezateplená časť | E28: 307.8 | I28: Odpor konštrukcie pri prechode tepla | L28: R0 = | M28: =M17+M26+M27 -> 7.014648 | Q28: Súčiniteľ prechodu tepla | T28: U = | U28: 0.22
A29: Odpor pri prestupe tepla na vnútornej strane k-cie | D29: Rsi = | E29: 0.13 | I29: Súčiniteľ prechodu tepla | L29: U = | M29: =1/(M17+M26+M27) -> 0.14255883
A30: Názov vrstvy konštrukcie | C30: dj [m] | D30: λj [W/(m.K)] | E30: Rj [m2.K/W]
A31: Vápennocementová omietka | C31: 0.012 | D31: 0.9 | E31: =C31/D31 -> 0.013333333
A32: betón ŽB | C32: 0.15 | D32: 1.7 | E32: =C32/D32 -> 0.088235294
A33: pórobetón | C33: 0.3 | D33: 0.3 | E33: =C33/D33 -> 1
A34: TI minerálna vlna | C34: 0.14 | D34: 0.04 | E34: =C34/D34 -> 3.5
A38: Celková hrúbka konštrukcie | C38: =SUM(C31:C36) -> 0.602 | D38: ∑Rj = | E38: =SUM(E31:E36) -> 4.6015686
A39: Odpor pri prestupe tepla na vonkajšej strane k-cie | D39: Rse = | E39: 0.04
A40: Odpor konštrukcie pri prechode tepla | D40: R0 = | E40: =E29+E38+E39 -> 4.7715686
A41: Súčiniteľ prechodu tepla | D41: U = | E41: =1/(E29+E38+E39) -> 0.20957469
A43: SO4 | B43: Obvodová stena Jedáleň | E43: 333
A44: Odpor pri prestupe tepla na vnútornej strane k-cie | D44: Rsi = | E44: 0.13
...

Sheet PodlahaTeren

Sheet OtvoroveKonstrukcie
A1: Ozn. | B1: Otvorové konštrukcie | C1: orientácia | H1: počet | I1: rozmer A x B | K1: obvod | L1: plocha | M1: Škára | N1: Uw | O1: SUMA S | P1: SUMA O | Q1: SUMA L | S1: posudenie vyhovuje nevuhovuje tabulka
C2: J | D2: V | E2: Z | F2: S | G2: H | H2: [ks] | I2: A [m] | J2: B [m] | K2: O [m] | L2: S [m2] | M2: L [m] | N2: [W/(m2.K)]
A3: OO1 | B3: plastové, izolačné 2-sklo | D3: 100 | H3: =SUM(C3:G3) -> 100 | I3: 1.5 | J3: 1.5 | K3: =2*(I3+J3) -> 6 | L3: =I3*J3 -> 2.25 | M3: =0.9*(2*I3+2*J3) -> 5.4 | N3: 1.5 | O3: =L3*H3 -> 225 | P3: =K3*H3 -> 600 | Q3: =M3 -> 5.4
A4: OO2 | B4: plastové, izolačné 2-sklo | D4: 2 | H4: =SUM(C4:G4) -> 2 | I4: 0.9 | J4: 1.5 | K4: =2*(I4+J4) -> 4.8 | L4: =I4*J4 -> 1.35 | M4: =0.9*(2*I4+2*J4) -> 4.32 | N4: 1.5 | O4: =L4*H4 -> 2.7 | P4: =K4*H4 -> 9.6 | Q4: =M4 -> 4.32
A5: OO3 | B5: plastové, izolačné 2-sklo | D5: 16 | H5: =SUM(C5:G5) -> 16 | I5: 2.1 | J5: 1.5 | K5: =2*(I5+J5) -> 7.2 | L5: =I5*J5 -> 3.15 | M5: =0.9*(2*I5+2*J5) -> 6.48 | N5: 1.5 | O5: =L5*H5 -> 50.4 | P5: =K5*H5 -> 115.2 | Q5: =M5 -> 6.48
A6: OO4 | B6: plastové, izolačné 2-sklo | D6: 4 | H6: =SUM(C6:G6) -> 4 | I6: 3 | J6: 1.5 | K6: =2*(I6+J6) -> 9 | L6: =I6*J6 -> 4.5 | M6: =0.9*(2*I6+2*J6) -> 8.1 | N6: 1.5 | O6: =L6*H6 -> 18 | P6: =K6*H6 -> 36 | Q6: =M6 -> 8.1
A7: OO5 | B7: plastové, izolačné 2-sklo | D7: 3 | H7: =SUM(C7:G7) -> 3 | I7: 1.2 | J7: 0.9 | K7: =2*(I7+J7) -> 4.2 | L7: =I7*J7 -> 1.08 | M7: =0.9*(2*I7+2*J7) -> 3.78 | N7: 1.5 | O7: =L7*H7 -> 3.24 | P7: =K7*H7 -> 12.6 | Q7: =M7 -> 3.78
A8: OO6 | B8: plastové, izolačné 2-sklo | D8: 1 | H8: =SUM(C8:G8) -> 1 | I8: 1.4 | J8: 1.35 | K8: =2*(I8+J8) -> 5.5 | L8: =I8*J8 -> 1.89 | M8: =0.9*(2*I8+2*J8) -> 4.95 | N8: 1.5 | O8: =L8*H8 -> 1.89 | P8: =K8*H8 -> 5.5 | Q8: =M8 -> 4.95
A9: OO7 | B9: plastové, izolačné 2-sklo | D9: 4 | H9: =SUM(C9:G9) -> 4 | I9: 1.35 | J9: 1.5 | K9: =2*(I9+J9) -> 5.7 | L9: =I9*J9 -> 2.025 | M9: =0.9*(2*I9+2*J9) -> 5.13 | N9: 1.5 | O9: =L9*H9 -> 8.1 | P9: =K9*H9 -> 22.8 | Q9: =M9 -> 5.13
A10: OO8 | B10: plastové, izolačné 2-sklo | D10: 1 | H10: =SUM(C10:G10) -> 1 | I10: 0.6 | J10: 1.5 | K10: =2*(I10+J10) -> 4.2 | L10: =I10*J10 -> 0.9 | M10: =0.9*(2*I10+2*J10) -> 3.78 | N10: 1.5 | O10: =L10*H10 -> 0.9 | P10: =K10*H10 -> 4.2 | Q10: =M10 -> 3.78
A11: OO9 | B11: plastové, izolačné 2-sklo | D11: 4 | H11: =SUM(C11:G11) -> 4 | I11: 2.7 | J11: 1.5 | K11: =2*(I11+J11) -> 8.4 | L11: =I11*J11 -> 4.05 | M11: =0.9*(2*I11+2*J11) -> 7.56 | N11: 1.5 | O11: =L11*H11 -> 16.2 | P11: =K11*H11 -> 33.6 | Q11: =M11 -> 7.56
A12: OO10 | B12: plastové, izolačné 2-sklo | C12: 1 | H12: =SUM(C12:G12) -> 1 | I12: 1.34 | J12: 1.5 | K12: =2*(I12+J12) -> 5.68 | L12: =I12*J12 -> 2.01 | M12: =0.9*(2*I12+2*J12) -> 5.112 | N12: 1.5 | O12: =L12*H12 -> 2.01 | P12: =K12*H12 -> 5.68 | Q12: =M12 -> 5.112
A13: OO11 | B13: plastové, izolačné 2-sklo | C13: 2 | H13: =SUM(C13:G13) -> 2 | I13: 2.4 | J13: 2.4 | K13: =2*(I13+J13) -> 9.6 | L13: =I13*J13 -> 5.76 | M13: =0.9*(2*I13+2*J13) -> 8.64 | N13: 1.5 | O13: =L13*H13 -> 11.52 | P13: =K13*H13 -> 19.2 | Q13: =M13 -> 8.64
A14: OO12 | B14: plastové, izolačné 2-sklo | C14: 2 | H14: =SUM(C14:G14) -> 2 | I14: 1.35 | J14: 1.5 | K14: =2*(I14+J14) -> 5.7 | L14: =I14*J14 -> 2.025 | M14: =0.9*(2*I14+2*J14) -> 5.13 | N14: 1.5 | O14: =L14*H14 -> 4.05 | P14: =K14*H14 -> 11.4 | Q14: =M14 -> 5.13
A15: OO13 | B15: plastové, izolačné 2-sklo | C15: 11 | H15: =SUM(C15:G15) -> 11 | I15: 1.42 | J15: 1.5 | K15: =2*(I15+J15) -> 5.84 | L15: =I15*J15 -> 2.13 | M15: =0.9*(2*I15+2*J15) -> 5.256 | N15: 1.5 | O15: =L15*H15 -> 23.43 | P15: =K15*H15 -> 64.24 | Q15: =M15 -> 5.256
